Backup failed for Site erpnexxt.local. Database or site_config.json may be corrupted
Traceback with variables (most recent call last):
  File "apps/frappe/frappe/commands/site.py", line 854, in backup
    odb = scheduled_backup(
      context = {'sites': ['erpnexxt.local'], 'force': False, 'verbose': True, 'profile': False}
      with_files = False
      backup_path = None
      backup_path_db = None
      backup_path_files = None
      backup_path_private_files = None
      backup_path_conf = None
      ignore_backup_conf = False
      verbose = True
      compress = False
      include = ''
      exclude = ''
      old_backup_metadata = False
      scheduled_backup = <function scheduled_backup at 0x108058040>
      exit_code = 0
      rollback_callback = None
      site = 'erpnexxt.local'
  File "apps/frappe/frappe/utils/backups.py", line 568, in scheduled_backup
    return new_backup(
      older_than = 6
      ignore_files = True
      backup_path = None
      backup_path_db = None
      backup_path_files = None
      backup_path_private_files = None
      backup_path_conf = None
      ignore_conf = False
      include_doctypes = ''
      exclude_doctypes = ''
      compress = False
      force = True
      verbose = True
      old_backup_metadata = False
      rollback_callback = <frappe.utils.CallbackManager object at 0x10829c4f0>
  File "apps/frappe/frappe/utils/backups.py", line 626, in new_backup
    odb.get_backup(older_than, ignore_files, force=force)
      older_than = 6
      ignore_files = True
      backup_path = None
      backup_path_db = None
      backup_path_files = None
      backup_path_private_files = None
      backup_path_conf = None
      ignore_conf = False
      include_doctypes = ''
      exclude_doctypes = ''
      compress = False
      force = True
      verbose = True
      old_backup_metadata = False
      rollback_callback = <frappe.utils.CallbackManager object at 0x10829c4f0>
      odb = <frappe.utils.backups.BackupGenerator object at 0x1080cad50>
  File "apps/frappe/frappe/utils/backups.py", line 195, in get_backup
    self.delete_if_step_fails(self.take_dump, self.backup_path_db)
      self = <frappe.utils.backups.BackupGenerator object at 0x1080cad50>
      older_than = 6
      ignore_files = True
      force = True
      last_db = False
      last_file = False
      last_private_file = False
      site_config_backup_path = False
  File "apps/frappe/frappe/utils/backups.py", line 520, in delete_if_step_fails
    raise e
      self = <frappe.utils.backups.BackupGenerator object at 0x1080cad50>
      step = <bound method BackupGenerator.take_dump of <frappe.utils.backups.BackupGenerator object at 0x1080cad50>>
      paths = ('./erpnexxt.local/private/backups/20250205_173004-erpnexxt_local-database.sql.gz',)
      path = './erpnexxt.local/private/backups/20250205_173004-erpnexxt_local-database.sql.gz'
  File "apps/frappe/frappe/utils/backups.py", line 515, in delete_if_step_fails
    step()
      self = <frappe.utils.backups.BackupGenerator object at 0x1080cad50>
      step = <bound method BackupGenerator.take_dump of <frappe.utils.backups.BackupGenerator object at 0x1080cad50>>
      paths = ('./erpnexxt.local/private/backups/20250205_173004-erpnexxt_local-database.sql.gz',)
      path = './erpnexxt.local/private/backups/20250205_173004-erpnexxt_local-database.sql.gz'
  File "apps/frappe/frappe/utils/backups.py", line 457, in take_dump
    frappe.throw(
      self = <frappe.utils.backups.BackupGenerator object at 0x1080cad50>
      shlex = <module 'shlex' from '/opt/homebrew/Cellar/python@3.11/3.11.11/Frameworks/Python.framework/Versions/3.11/lib/python3.11/shlex.py'>
      frappe = <module 'frappe' from 'apps/frappe/frappe/__init__.py'>
      get_app_branch = <function get_app_branch at 0x10802bce0>
      gzip_exc = '/usr/bin/gzip'
      database_header_content = ['begin frappe metadata', '[frappe]', 'version = 15.54.1', 'branch = version-15', 'end frappe metadata', '']
      generated_header = '-- begin frappe metadata\n-- [frappe]\n-- version = 15.54.1\n-- branch = version-15\n-- end frappe metadata\n-- \n'
      f = <_io.TextIOWrapper name='./erpnexxt.local/private/backups/20250205_173004-erpnexxt_local-database.sql.gz' encoding='UTF-8'>
      cmd = []
      extra = []
      get_command = <function get_command at 0x10801a7a0>
      bin = None
      args = ['--user=_e7903427184a81b1', '--host=127.0.0.1', '--port=3306', '--password=eHVakHXsPB0Hhyx0', '--single-transaction', '--quick', '--lock-tables=false', '_e7903427184a81b1']
      bin_name = 'mariadb-dump'
  File "apps/frappe/frappe/__init__.py", line 603, in throw
    msgprint(
      msg = 'mariadb-dump not found in PATH! This is required to take a backup.'
      exc = <class 'frappe.exceptions.ExecutableNotFound'>
      title = None
      is_minimizable = False
      wide = False
      as_list = False
      primary_action = None
  File "apps/frappe/frappe/__init__.py", line 568, in msgprint
    _raise_exception()
      msg = 'mariadb-dump not found in PATH! This is required to take a backup.'
      title = None
      raise_exception = <class 'frappe.exceptions.ExecutableNotFound'>
      as_table = False
      as_list = False
      indicator = 'red'
      alert = False
      primary_action = None
      is_minimizable = False
      wide = False
      realtime = False
      sys = <module 'sys' (built-in)>
      _raise_exception = <function msgprint.<locals>._raise_exception at 0x10845b740>
      inspect = <module 'inspect' from '/opt/homebrew/Cellar/python@3.11/3.11.11/Frameworks/Python.framework/Versions/3.11/lib/python3.11/inspect.py'>
      out = {'message': 'mariadb-dump not found in PATH! This is required to take a backup.', 'title': 'Message', 'indicator': 'red', 'raise_exception': 1, '__frappe_exc_id': '0bea3803403152efbc23bf6f6c7e3b07d2c5d3aae4bcb39c2e885653'}
  File "apps/frappe/frappe/__init__.py", line 519, in _raise_exception
    raise exc
      exc = ExecutableNotFound('mariadb-dump not found in PATH! This is required to take a backup.')
      inspect = <module 'inspect' from '/opt/homebrew/Cellar/python@3.11/3.11.11/Frameworks/Python.framework/Versions/3.11/lib/python3.11/inspect.py'>
      msg = 'mariadb-dump not found in PATH! This is required to take a backup.'
      out = {'message': 'mariadb-dump not found in PATH! This is required to take a backup.', 'title': 'Message', 'indicator': 'red', 'raise_exception': 1, '__frappe_exc_id': '0bea3803403152efbc23bf6f6c7e3b07d2c5d3aae4bcb39c2e885653'}
      raise_exception = <class 'frappe.exceptions.ExecutableNotFound'>
frappe.exceptions.ExecutableNotFound: mariadb-dump not found in PATH! This is required to take a backup.
Backup failed for Site erpnexxt.local. Database or site_config.json may be corrupted
Traceback with variables (most recent call last):
  File "apps/frappe/frappe/commands/site.py", line 854, in backup
    odb = scheduled_backup(
      context = {'sites': ['erpnexxt.local'], 'force': False, 'verbose': True, 'profile': False}
      with_files = False
      backup_path = None
      backup_path_db = None
      backup_path_files = None
      backup_path_private_files = None
      backup_path_conf = None
      ignore_backup_conf = False
      verbose = True
      compress = False
      include = ''
      exclude = ''
      old_backup_metadata = False
      scheduled_backup = <function scheduled_backup at 0x105500040>
      exit_code = 0
      rollback_callback = None
      site = 'erpnexxt.local'
  File "apps/frappe/frappe/utils/backups.py", line 568, in scheduled_backup
    return new_backup(
      older_than = 6
      ignore_files = True
      backup_path = None
      backup_path_db = None
      backup_path_files = None
      backup_path_private_files = None
      backup_path_conf = None
      ignore_conf = False
      include_doctypes = ''
      exclude_doctypes = ''
      compress = False
      force = True
      verbose = True
      old_backup_metadata = False
      rollback_callback = <frappe.utils.CallbackManager object at 0x1057444f0>
  File "apps/frappe/frappe/utils/backups.py", line 626, in new_backup
    odb.get_backup(older_than, ignore_files, force=force)
      older_than = 6
      ignore_files = True
      backup_path = None
      backup_path_db = None
      backup_path_files = None
      backup_path_private_files = None
      backup_path_conf = None
      ignore_conf = False
      include_doctypes = ''
      exclude_doctypes = ''
      compress = False
      force = True
      verbose = True
      old_backup_metadata = False
      rollback_callback = <frappe.utils.CallbackManager object at 0x1057444f0>
      odb = <frappe.utils.backups.BackupGenerator object at 0x105725a50>
  File "apps/frappe/frappe/utils/backups.py", line 195, in get_backup
    self.delete_if_step_fails(self.take_dump, self.backup_path_db)
      self = <frappe.utils.backups.BackupGenerator object at 0x105725a50>
      older_than = 6
      ignore_files = True
      force = True
      last_db = False
      last_file = False
      last_private_file = False
      site_config_backup_path = False
  File "apps/frappe/frappe/utils/backups.py", line 520, in delete_if_step_fails
    raise e
      self = <frappe.utils.backups.BackupGenerator object at 0x105725a50>
      step = <bound method BackupGenerator.take_dump of <frappe.utils.backups.BackupGenerator object at 0x105725a50>>
      paths = ('./erpnexxt.local/private/backups/20250205_233002-erpnexxt_local-database.sql.gz',)
      path = './erpnexxt.local/private/backups/20250205_233002-erpnexxt_local-database.sql.gz'
  File "apps/frappe/frappe/utils/backups.py", line 515, in delete_if_step_fails
    step()
      self = <frappe.utils.backups.BackupGenerator object at 0x105725a50>
      step = <bound method BackupGenerator.take_dump of <frappe.utils.backups.BackupGenerator object at 0x105725a50>>
      paths = ('./erpnexxt.local/private/backups/20250205_233002-erpnexxt_local-database.sql.gz',)
      path = './erpnexxt.local/private/backups/20250205_233002-erpnexxt_local-database.sql.gz'
  File "apps/frappe/frappe/utils/backups.py", line 457, in take_dump
    frappe.throw(
      self = <frappe.utils.backups.BackupGenerator object at 0x105725a50>
      shlex = <module 'shlex' from '/opt/homebrew/Cellar/python@3.11/3.11.11/Frameworks/Python.framework/Versions/3.11/lib/python3.11/shlex.py'>
      frappe = <module 'frappe' from 'apps/frappe/frappe/__init__.py'>
      get_app_branch = <function get_app_branch at 0x1054d3ce0>
      gzip_exc = '/usr/bin/gzip'
      database_header_content = ['begin frappe metadata', '[frappe]', 'version = 15.54.1', 'branch = version-15', 'end frappe metadata', '']
      generated_header = '-- begin frappe metadata\n-- [frappe]\n-- version = 15.54.1\n-- branch = version-15\n-- end frappe metadata\n-- \n'
      f = <_io.TextIOWrapper name='./erpnexxt.local/private/backups/20250205_233002-erpnexxt_local-database.sql.gz' encoding='UTF-8'>
      cmd = []
      extra = []
      get_command = <function get_command at 0x1054c27a0>
      bin = None
      args = ['--user=_e7903427184a81b1', '--host=127.0.0.1', '--port=3306', '--password=eHVakHXsPB0Hhyx0', '--single-transaction', '--quick', '--lock-tables=false', '_e7903427184a81b1']
      bin_name = 'mariadb-dump'
  File "apps/frappe/frappe/__init__.py", line 603, in throw
    msgprint(
      msg = 'mariadb-dump not found in PATH! This is required to take a backup.'
      exc = <class 'frappe.exceptions.ExecutableNotFound'>
      title = None
      is_minimizable = False
      wide = False
      as_list = False
      primary_action = None
  File "apps/frappe/frappe/__init__.py", line 568, in msgprint
    _raise_exception()
      msg = 'mariadb-dump not found in PATH! This is required to take a backup.'
      title = None
      raise_exception = <class 'frappe.exceptions.ExecutableNotFound'>
      as_table = False
      as_list = False
      indicator = 'red'
      alert = False
      primary_action = None
      is_minimizable = False
      wide = False
      realtime = False
      sys = <module 'sys' (built-in)>
      _raise_exception = <function msgprint.<locals>._raise_exception at 0x105903740>
      inspect = <module 'inspect' from '/opt/homebrew/Cellar/python@3.11/3.11.11/Frameworks/Python.framework/Versions/3.11/lib/python3.11/inspect.py'>
      out = {'message': 'mariadb-dump not found in PATH! This is required to take a backup.', 'title': 'Message', 'indicator': 'red', 'raise_exception': 1, '__frappe_exc_id': '2f133229d17abe7d889185b7ea4cab3184dfd544e7fa3d0ce7b333c7'}
  File "apps/frappe/frappe/__init__.py", line 519, in _raise_exception
    raise exc
      exc = ExecutableNotFound('mariadb-dump not found in PATH! This is required to take a backup.')
      inspect = <module 'inspect' from '/opt/homebrew/Cellar/python@3.11/3.11.11/Frameworks/Python.framework/Versions/3.11/lib/python3.11/inspect.py'>
      msg = 'mariadb-dump not found in PATH! This is required to take a backup.'
      out = {'message': 'mariadb-dump not found in PATH! This is required to take a backup.', 'title': 'Message', 'indicator': 'red', 'raise_exception': 1, '__frappe_exc_id': '2f133229d17abe7d889185b7ea4cab3184dfd544e7fa3d0ce7b333c7'}
      raise_exception = <class 'frappe.exceptions.ExecutableNotFound'>
frappe.exceptions.ExecutableNotFound: mariadb-dump not found in PATH! This is required to take a backup.
Backup failed for Site erpnexxt.local. Database or site_config.json may be corrupted
Traceback with variables (most recent call last):
  File "apps/frappe/frappe/commands/site.py", line 854, in backup
    odb = scheduled_backup(
      context = {'sites': ['erpnexxt.local'], 'force': False, 'verbose': True, 'profile': False}
      with_files = False
      backup_path = None
      backup_path_db = None
      backup_path_files = None
      backup_path_private_files = None
      backup_path_conf = None
      ignore_backup_conf = False
      verbose = True
      compress = False
      include = ''
      exclude = ''
      old_backup_metadata = False
      scheduled_backup = <function scheduled_backup at 0x107e74040>
      exit_code = 0
      rollback_callback = None
      site = 'erpnexxt.local'
  File "apps/frappe/frappe/utils/backups.py", line 568, in scheduled_backup
    return new_backup(
      older_than = 6
      ignore_files = True
      backup_path = None
      backup_path_db = None
      backup_path_files = None
      backup_path_private_files = None
      backup_path_conf = None
      ignore_conf = False
      include_doctypes = ''
      exclude_doctypes = ''
      compress = False
      force = True
      verbose = True
      old_backup_metadata = False
      rollback_callback = <frappe.utils.CallbackManager object at 0x1080b84f0>
  File "apps/frappe/frappe/utils/backups.py", line 626, in new_backup
    odb.get_backup(older_than, ignore_files, force=force)
      older_than = 6
      ignore_files = True
      backup_path = None
      backup_path_db = None
      backup_path_files = None
      backup_path_private_files = None
      backup_path_conf = None
      ignore_conf = False
      include_doctypes = ''
      exclude_doctypes = ''
      compress = False
      force = True
      verbose = True
      old_backup_metadata = False
      rollback_callback = <frappe.utils.CallbackManager object at 0x1080b84f0>
      odb = <frappe.utils.backups.BackupGenerator object at 0x108099cd0>
  File "apps/frappe/frappe/utils/backups.py", line 195, in get_backup
    self.delete_if_step_fails(self.take_dump, self.backup_path_db)
      self = <frappe.utils.backups.BackupGenerator object at 0x108099cd0>
      older_than = 6
      ignore_files = True
      force = True
      last_db = False
      last_file = False
      last_private_file = False
      site_config_backup_path = False
  File "apps/frappe/frappe/utils/backups.py", line 520, in delete_if_step_fails
    raise e
      self = <frappe.utils.backups.BackupGenerator object at 0x108099cd0>
      step = <bound method BackupGenerator.take_dump of <frappe.utils.backups.BackupGenerator object at 0x108099cd0>>
      paths = ('./erpnexxt.local/private/backups/20250206_113012-erpnexxt_local-database.sql.gz',)
      path = './erpnexxt.local/private/backups/20250206_113012-erpnexxt_local-database.sql.gz'
  File "apps/frappe/frappe/utils/backups.py", line 515, in delete_if_step_fails
    step()
      self = <frappe.utils.backups.BackupGenerator object at 0x108099cd0>
      step = <bound method BackupGenerator.take_dump of <frappe.utils.backups.BackupGenerator object at 0x108099cd0>>
      paths = ('./erpnexxt.local/private/backups/20250206_113012-erpnexxt_local-database.sql.gz',)
      path = './erpnexxt.local/private/backups/20250206_113012-erpnexxt_local-database.sql.gz'
  File "apps/frappe/frappe/utils/backups.py", line 457, in take_dump
    frappe.throw(
      self = <frappe.utils.backups.BackupGenerator object at 0x108099cd0>
      shlex = <module 'shlex' from '/opt/homebrew/Cellar/python@3.11/3.11.11/Frameworks/Python.framework/Versions/3.11/lib/python3.11/shlex.py'>
      frappe = <module 'frappe' from 'apps/frappe/frappe/__init__.py'>
      get_app_branch = <function get_app_branch at 0x107e47ce0>
      gzip_exc = '/usr/bin/gzip'
      database_header_content = ['begin frappe metadata', '[frappe]', 'version = 15.54.1', 'branch = version-15', 'end frappe metadata', '']
      generated_header = '-- begin frappe metadata\n-- [frappe]\n-- version = 15.54.1\n-- branch = version-15\n-- end frappe metadata\n-- \n'
      f = <_io.TextIOWrapper name='./erpnexxt.local/private/backups/20250206_113012-erpnexxt_local-database.sql.gz' encoding='UTF-8'>
      cmd = []
      extra = []
      get_command = <function get_command at 0x107e367a0>
      bin = None
      args = ['--user=_e7903427184a81b1', '--host=127.0.0.1', '--port=3306', '--password=eHVakHXsPB0Hhyx0', '--single-transaction', '--quick', '--lock-tables=false', '_e7903427184a81b1']
      bin_name = 'mariadb-dump'
  File "apps/frappe/frappe/__init__.py", line 603, in throw
    msgprint(
      msg = 'mariadb-dump not found in PATH! This is required to take a backup.'
      exc = <class 'frappe.exceptions.ExecutableNotFound'>
      title = None
      is_minimizable = False
      wide = False
      as_list = False
      primary_action = None
  File "apps/frappe/frappe/__init__.py", line 568, in msgprint
    _raise_exception()
      msg = 'mariadb-dump not found in PATH! This is required to take a backup.'
      title = None
      raise_exception = <class 'frappe.exceptions.ExecutableNotFound'>
      as_table = False
      as_list = False
      indicator = 'red'
      alert = False
      primary_action = None
      is_minimizable = False
      wide = False
      realtime = False
      sys = <module 'sys' (built-in)>
      _raise_exception = <function msgprint.<locals>._raise_exception at 0x108277740>
      inspect = <module 'inspect' from '/opt/homebrew/Cellar/python@3.11/3.11.11/Frameworks/Python.framework/Versions/3.11/lib/python3.11/inspect.py'>
      out = {'message': 'mariadb-dump not found in PATH! This is required to take a backup.', 'title': 'Message', 'indicator': 'red', 'raise_exception': 1, '__frappe_exc_id': 'ce7228bf276b902d1944155f4205c836823d014f6d831e0147a3e805'}
  File "apps/frappe/frappe/__init__.py", line 519, in _raise_exception
    raise exc
      exc = ExecutableNotFound('mariadb-dump not found in PATH! This is required to take a backup.')
      inspect = <module 'inspect' from '/opt/homebrew/Cellar/python@3.11/3.11.11/Frameworks/Python.framework/Versions/3.11/lib/python3.11/inspect.py'>
      msg = 'mariadb-dump not found in PATH! This is required to take a backup.'
      out = {'message': 'mariadb-dump not found in PATH! This is required to take a backup.', 'title': 'Message', 'indicator': 'red', 'raise_exception': 1, '__frappe_exc_id': 'ce7228bf276b902d1944155f4205c836823d014f6d831e0147a3e805'}
      raise_exception = <class 'frappe.exceptions.ExecutableNotFound'>
frappe.exceptions.ExecutableNotFound: mariadb-dump not found in PATH! This is required to take a backup.
Backup failed for Site erpnexxt.local. Database or site_config.json may be corrupted
Traceback with variables (most recent call last):
  File "apps/frappe/frappe/commands/site.py", line 854, in backup
    odb = scheduled_backup(
      context = {'sites': ['erpnexxt.local'], 'force': False, 'verbose': True, 'profile': False}
      with_files = False
      backup_path = None
      backup_path_db = None
      backup_path_files = None
      backup_path_private_files = None
      backup_path_conf = None
      ignore_backup_conf = False
      verbose = True
      compress = False
      include = ''
      exclude = ''
      old_backup_metadata = False
      scheduled_backup = <function scheduled_backup at 0x10350c040>
      exit_code = 0
      rollback_callback = None
      site = 'erpnexxt.local'
  File "apps/frappe/frappe/utils/backups.py", line 568, in scheduled_backup
    return new_backup(
      older_than = 6
      ignore_files = True
      backup_path = None
      backup_path_db = None
      backup_path_files = None
      backup_path_private_files = None
      backup_path_conf = None
      ignore_conf = False
      include_doctypes = ''
      exclude_doctypes = ''
      compress = False
      force = True
      verbose = True
      old_backup_metadata = False
      rollback_callback = <frappe.utils.CallbackManager object at 0x1037504f0>
  File "apps/frappe/frappe/utils/backups.py", line 626, in new_backup
    odb.get_backup(older_than, ignore_files, force=force)
      older_than = 6
      ignore_files = True
      backup_path = None
      backup_path_db = None
      backup_path_files = None
      backup_path_private_files = None
      backup_path_conf = None
      ignore_conf = False
      include_doctypes = ''
      exclude_doctypes = ''
      compress = False
      force = True
      verbose = True
      old_backup_metadata = False
      rollback_callback = <frappe.utils.CallbackManager object at 0x1037504f0>
      odb = <frappe.utils.backups.BackupGenerator object at 0x103731790>
  File "apps/frappe/frappe/utils/backups.py", line 195, in get_backup
    self.delete_if_step_fails(self.take_dump, self.backup_path_db)
      self = <frappe.utils.backups.BackupGenerator object at 0x103731790>
      older_than = 6
      ignore_files = True
      force = True
      last_db = False
      last_file = False
      last_private_file = False
      site_config_backup_path = False
  File "apps/frappe/frappe/utils/backups.py", line 520, in delete_if_step_fails
    raise e
      self = <frappe.utils.backups.BackupGenerator object at 0x103731790>
      step = <bound method BackupGenerator.take_dump of <frappe.utils.backups.BackupGenerator object at 0x103731790>>
      paths = ('./erpnexxt.local/private/backups/20250206_233453-erpnexxt_local-database.sql.gz',)
      path = './erpnexxt.local/private/backups/20250206_233453-erpnexxt_local-database.sql.gz'
  File "apps/frappe/frappe/utils/backups.py", line 515, in delete_if_step_fails
    step()
      self = <frappe.utils.backups.BackupGenerator object at 0x103731790>
      step = <bound method BackupGenerator.take_dump of <frappe.utils.backups.BackupGenerator object at 0x103731790>>
      paths = ('./erpnexxt.local/private/backups/20250206_233453-erpnexxt_local-database.sql.gz',)
      path = './erpnexxt.local/private/backups/20250206_233453-erpnexxt_local-database.sql.gz'
  File "apps/frappe/frappe/utils/backups.py", line 457, in take_dump
    frappe.throw(
      self = <frappe.utils.backups.BackupGenerator object at 0x103731790>
      shlex = <module 'shlex' from '/opt/homebrew/Cellar/python@3.11/3.11.11/Frameworks/Python.framework/Versions/3.11/lib/python3.11/shlex.py'>
      frappe = <module 'frappe' from 'apps/frappe/frappe/__init__.py'>
      get_app_branch = <function get_app_branch at 0x1034dfce0>
      gzip_exc = '/usr/bin/gzip'
      database_header_content = ['begin frappe metadata', '[frappe]', 'version = 15.54.1', 'branch = version-15', 'end frappe metadata', '']
      generated_header = '-- begin frappe metadata\n-- [frappe]\n-- version = 15.54.1\n-- branch = version-15\n-- end frappe metadata\n-- \n'
      f = <_io.TextIOWrapper name='./erpnexxt.local/private/backups/20250206_233453-erpnexxt_local-database.sql.gz' encoding='UTF-8'>
      cmd = []
      extra = []
      get_command = <function get_command at 0x1034ce7a0>
      bin = None
      args = ['--user=_e7903427184a81b1', '--host=127.0.0.1', '--port=3306', '--password=eHVakHXsPB0Hhyx0', '--single-transaction', '--quick', '--lock-tables=false', '_e7903427184a81b1']
      bin_name = 'mariadb-dump'
  File "apps/frappe/frappe/__init__.py", line 603, in throw
    msgprint(
      msg = 'mariadb-dump not found in PATH! This is required to take a backup.'
      exc = <class 'frappe.exceptions.ExecutableNotFound'>
      title = None
      is_minimizable = False
      wide = False
      as_list = False
      primary_action = None
  File "apps/frappe/frappe/__init__.py", line 568, in msgprint
    _raise_exception()
      msg = 'mariadb-dump not found in PATH! This is required to take a backup.'
      title = None
      raise_exception = <class 'frappe.exceptions.ExecutableNotFound'>
      as_table = False
      as_list = False
      indicator = 'red'
      alert = False
      primary_action = None
      is_minimizable = False
      wide = False
      realtime = False
      sys = <module 'sys' (built-in)>
      _raise_exception = <function msgprint.<locals>._raise_exception at 0x10390f740>
      inspect = <module 'inspect' from '/opt/homebrew/Cellar/python@3.11/3.11.11/Frameworks/Python.framework/Versions/3.11/lib/python3.11/inspect.py'>
      out = {'message': 'mariadb-dump not found in PATH! This is required to take a backup.', 'title': 'Message', 'indicator': 'red', 'raise_exception': 1, '__frappe_exc_id': '0b0c6937bbcd29cb80cbb948e51681d4e32cc151eb1135467fd9e40f'}
  File "apps/frappe/frappe/__init__.py", line 519, in _raise_exception
    raise exc
      exc = ExecutableNotFound('mariadb-dump not found in PATH! This is required to take a backup.')
      inspect = <module 'inspect' from '/opt/homebrew/Cellar/python@3.11/3.11.11/Frameworks/Python.framework/Versions/3.11/lib/python3.11/inspect.py'>
      msg = 'mariadb-dump not found in PATH! This is required to take a backup.'
      out = {'message': 'mariadb-dump not found in PATH! This is required to take a backup.', 'title': 'Message', 'indicator': 'red', 'raise_exception': 1, '__frappe_exc_id': '0b0c6937bbcd29cb80cbb948e51681d4e32cc151eb1135467fd9e40f'}
      raise_exception = <class 'frappe.exceptions.ExecutableNotFound'>
frappe.exceptions.ExecutableNotFound: mariadb-dump not found in PATH! This is required to take a backup.
Backup failed for Site erpnexxt.local. Database or site_config.json may be corrupted
Traceback with variables (most recent call last):
  File "apps/frappe/frappe/commands/site.py", line 854, in backup
    odb = scheduled_backup(
      context = {'sites': ['erpnexxt.local'], 'force': False, 'verbose': True, 'profile': False}
      with_files = False
      backup_path = None
      backup_path_db = None
      backup_path_files = None
      backup_path_private_files = None
      backup_path_conf = None
      ignore_backup_conf = False
      verbose = True
      compress = False
      include = ''
      exclude = ''
      old_backup_metadata = False
      scheduled_backup = <function scheduled_backup at 0x103d74040>
      exit_code = 0
      rollback_callback = None
      site = 'erpnexxt.local'
  File "apps/frappe/frappe/utils/backups.py", line 568, in scheduled_backup
    return new_backup(
      older_than = 6
      ignore_files = True
      backup_path = None
      backup_path_db = None
      backup_path_files = None
      backup_path_private_files = None
      backup_path_conf = None
      ignore_conf = False
      include_doctypes = ''
      exclude_doctypes = ''
      compress = False
      force = True
      verbose = True
      old_backup_metadata = False
      rollback_callback = <frappe.utils.CallbackManager object at 0x103fbc1f0>
  File "apps/frappe/frappe/utils/backups.py", line 626, in new_backup
    odb.get_backup(older_than, ignore_files, force=force)
      older_than = 6
      ignore_files = True
      backup_path = None
      backup_path_db = None
      backup_path_files = None
      backup_path_private_files = None
      backup_path_conf = None
      ignore_conf = False
      include_doctypes = ''
      exclude_doctypes = ''
      compress = False
      force = True
      verbose = True
      old_backup_metadata = False
      rollback_callback = <frappe.utils.CallbackManager object at 0x103fbc1f0>
      odb = <frappe.utils.backups.BackupGenerator object at 0x103f99c10>
  File "apps/frappe/frappe/utils/backups.py", line 195, in get_backup
    self.delete_if_step_fails(self.take_dump, self.backup_path_db)
      self = <frappe.utils.backups.BackupGenerator object at 0x103f99c10>
      older_than = 6
      ignore_files = True
      force = True
      last_db = False
      last_file = False
      last_private_file = False
      site_config_backup_path = False
  File "apps/frappe/frappe/utils/backups.py", line 520, in delete_if_step_fails
    raise e
      self = <frappe.utils.backups.BackupGenerator object at 0x103f99c10>
      step = <bound method BackupGenerator.take_dump of <frappe.utils.backups.BackupGenerator object at 0x103f99c10>>
      paths = ('./erpnexxt.local/private/backups/20250208_000005-erpnexxt_local-database.sql.gz',)
      path = './erpnexxt.local/private/backups/20250208_000005-erpnexxt_local-database.sql.gz'
  File "apps/frappe/frappe/utils/backups.py", line 515, in delete_if_step_fails
    step()
      self = <frappe.utils.backups.BackupGenerator object at 0x103f99c10>
      step = <bound method BackupGenerator.take_dump of <frappe.utils.backups.BackupGenerator object at 0x103f99c10>>
      paths = ('./erpnexxt.local/private/backups/20250208_000005-erpnexxt_local-database.sql.gz',)
      path = './erpnexxt.local/private/backups/20250208_000005-erpnexxt_local-database.sql.gz'
  File "apps/frappe/frappe/utils/backups.py", line 457, in take_dump
    frappe.throw(
      self = <frappe.utils.backups.BackupGenerator object at 0x103f99c10>
      shlex = <module 'shlex' from '/opt/homebrew/Cellar/python@3.11/3.11.11/Frameworks/Python.framework/Versions/3.11/lib/python3.11/shlex.py'>
      frappe = <module 'frappe' from 'apps/frappe/frappe/__init__.py'>
      get_app_branch = <function get_app_branch at 0x103d47ce0>
      gzip_exc = '/usr/bin/gzip'
      database_header_content = ['begin frappe metadata', '[frappe]', 'version = 15.54.1', 'branch = version-15', 'end frappe metadata', '']
      generated_header = '-- begin frappe metadata\n-- [frappe]\n-- version = 15.54.1\n-- branch = version-15\n-- end frappe metadata\n-- \n'
      f = <_io.TextIOWrapper name='./erpnexxt.local/private/backups/20250208_000005-erpnexxt_local-database.sql.gz' encoding='UTF-8'>
      cmd = []
      extra = []
      get_command = <function get_command at 0x103d367a0>
      bin = None
      args = ['--user=_e7903427184a81b1', '--host=127.0.0.1', '--port=3306', '--password=eHVakHXsPB0Hhyx0', '--single-transaction', '--quick', '--lock-tables=false', '_e7903427184a81b1']
      bin_name = 'mariadb-dump'
  File "apps/frappe/frappe/__init__.py", line 603, in throw
    msgprint(
      msg = 'mariadb-dump not found in PATH! This is required to take a backup.'
      exc = <class 'frappe.exceptions.ExecutableNotFound'>
      title = None
      is_minimizable = False
      wide = False
      as_list = False
      primary_action = None
  File "apps/frappe/frappe/__init__.py", line 568, in msgprint
    _raise_exception()
      msg = 'mariadb-dump not found in PATH! This is required to take a backup.'
      title = None
      raise_exception = <class 'frappe.exceptions.ExecutableNotFound'>
      as_table = False
      as_list = False
      indicator = 'red'
      alert = False
      primary_action = None
      is_minimizable = False
      wide = False
      realtime = False
      sys = <module 'sys' (built-in)>
      _raise_exception = <function msgprint.<locals>._raise_exception at 0x101d49da0>
      inspect = <module 'inspect' from '/opt/homebrew/Cellar/python@3.11/3.11.11/Frameworks/Python.framework/Versions/3.11/lib/python3.11/inspect.py'>
      out = {'message': 'mariadb-dump not found in PATH! This is required to take a backup.', 'title': 'Message', 'indicator': 'red', 'raise_exception': 1, '__frappe_exc_id': 'd15c2850e62677924c0a6d197819f33b0d97b6c22fbd8325c25481a1'}
  File "apps/frappe/frappe/__init__.py", line 519, in _raise_exception
    raise exc
      exc = ExecutableNotFound('mariadb-dump not found in PATH! This is required to take a backup.')
      inspect = <module 'inspect' from '/opt/homebrew/Cellar/python@3.11/3.11.11/Frameworks/Python.framework/Versions/3.11/lib/python3.11/inspect.py'>
      msg = 'mariadb-dump not found in PATH! This is required to take a backup.'
      out = {'message': 'mariadb-dump not found in PATH! This is required to take a backup.', 'title': 'Message', 'indicator': 'red', 'raise_exception': 1, '__frappe_exc_id': 'd15c2850e62677924c0a6d197819f33b0d97b6c22fbd8325c25481a1'}
      raise_exception = <class 'frappe.exceptions.ExecutableNotFound'>
frappe.exceptions.ExecutableNotFound: mariadb-dump not found in PATH! This is required to take a backup.
Backup failed for Site erpnexxt.local. Database or site_config.json may be corrupted
Traceback with variables (most recent call last):
  File "apps/frappe/frappe/commands/site.py", line 854, in backup
    odb = scheduled_backup(
      context = {'sites': ['erpnexxt.local'], 'force': False, 'verbose': True, 'profile': False}
      with_files = False
      backup_path = None
      backup_path_db = None
      backup_path_files = None
      backup_path_private_files = None
      backup_path_conf = None
      ignore_backup_conf = False
      verbose = True
      compress = False
      include = ''
      exclude = ''
      old_backup_metadata = False
      scheduled_backup = <function scheduled_backup at 0x1032f8040>
      exit_code = 0
      rollback_callback = None
      site = 'erpnexxt.local'
  File "apps/frappe/frappe/utils/backups.py", line 568, in scheduled_backup
    return new_backup(
      older_than = 6
      ignore_files = True
      backup_path = None
      backup_path_db = None
      backup_path_files = None
      backup_path_private_files = None
      backup_path_conf = None
      ignore_conf = False
      include_doctypes = ''
      exclude_doctypes = ''
      compress = False
      force = True
      verbose = True
      old_backup_metadata = False
      rollback_callback = <frappe.utils.CallbackManager object at 0x104cbc1f0>
  File "apps/frappe/frappe/utils/backups.py", line 626, in new_backup
    odb.get_backup(older_than, ignore_files, force=force)
      older_than = 6
      ignore_files = True
      backup_path = None
      backup_path_db = None
      backup_path_files = None
      backup_path_private_files = None
      backup_path_conf = None
      ignore_conf = False
      include_doctypes = ''
      exclude_doctypes = ''
      compress = False
      force = True
      verbose = True
      old_backup_metadata = False
      rollback_callback = <frappe.utils.CallbackManager object at 0x104cbc1f0>
      odb = <frappe.utils.backups.BackupGenerator object at 0x104c99a90>
  File "apps/frappe/frappe/utils/backups.py", line 195, in get_backup
    self.delete_if_step_fails(self.take_dump, self.backup_path_db)
      self = <frappe.utils.backups.BackupGenerator object at 0x104c99a90>
      older_than = 6
      ignore_files = True
      force = True
      last_db = False
      last_file = False
      last_private_file = False
      site_config_backup_path = False
  File "apps/frappe/frappe/utils/backups.py", line 520, in delete_if_step_fails
    raise e
      self = <frappe.utils.backups.BackupGenerator object at 0x104c99a90>
      step = <bound method BackupGenerator.take_dump of <frappe.utils.backups.BackupGenerator object at 0x104c99a90>>
      paths = ('./erpnexxt.local/private/backups/20250209_200007-erpnexxt_local-database.sql.gz',)
      path = './erpnexxt.local/private/backups/20250209_200007-erpnexxt_local-database.sql.gz'
  File "apps/frappe/frappe/utils/backups.py", line 515, in delete_if_step_fails
    step()
      self = <frappe.utils.backups.BackupGenerator object at 0x104c99a90>
      step = <bound method BackupGenerator.take_dump of <frappe.utils.backups.BackupGenerator object at 0x104c99a90>>
      paths = ('./erpnexxt.local/private/backups/20250209_200007-erpnexxt_local-database.sql.gz',)
      path = './erpnexxt.local/private/backups/20250209_200007-erpnexxt_local-database.sql.gz'
  File "apps/frappe/frappe/utils/backups.py", line 457, in take_dump
    frappe.throw(
      self = <frappe.utils.backups.BackupGenerator object at 0x104c99a90>
      shlex = <module 'shlex' from '/opt/homebrew/Cellar/python@3.11/3.11.11/Frameworks/Python.framework/Versions/3.11/lib/python3.11/shlex.py'>
      frappe = <module 'frappe' from 'apps/frappe/frappe/__init__.py'>
      get_app_branch = <function get_app_branch at 0x1032cbce0>
      gzip_exc = '/usr/bin/gzip'
      database_header_content = ['begin frappe metadata', '[frappe]', 'version = 15.54.1', 'branch = version-15', 'end frappe metadata', '']
      generated_header = '-- begin frappe metadata\n-- [frappe]\n-- version = 15.54.1\n-- branch = version-15\n-- end frappe metadata\n-- \n'
      f = <_io.TextIOWrapper name='./erpnexxt.local/private/backups/20250209_200007-erpnexxt_local-database.sql.gz' encoding='UTF-8'>
      cmd = []
      extra = []
      get_command = <function get_command at 0x1032ba7a0>
      bin = None
      args = ['--user=_e7903427184a81b1', '--host=127.0.0.1', '--port=3306', '--password=eHVakHXsPB0Hhyx0', '--single-transaction', '--quick', '--lock-tables=false', '_e7903427184a81b1']
      bin_name = 'mariadb-dump'
  File "apps/frappe/frappe/__init__.py", line 603, in throw
    msgprint(
      msg = 'mariadb-dump not found in PATH! This is required to take a backup.'
      exc = <class 'frappe.exceptions.ExecutableNotFound'>
      title = None
      is_minimizable = False
      wide = False
      as_list = False
      primary_action = None
  File "apps/frappe/frappe/__init__.py", line 568, in msgprint
    _raise_exception()
      msg = 'mariadb-dump not found in PATH! This is required to take a backup.'
      title = None
      raise_exception = <class 'frappe.exceptions.ExecutableNotFound'>
      as_table = False
      as_list = False
      indicator = 'red'
      alert = False
      primary_action = None
      is_minimizable = False
      wide = False
      realtime = False
      sys = <module 'sys' (built-in)>
      _raise_exception = <function msgprint.<locals>._raise_exception at 0x1016b5da0>
      inspect = <module 'inspect' from '/opt/homebrew/Cellar/python@3.11/3.11.11/Frameworks/Python.framework/Versions/3.11/lib/python3.11/inspect.py'>
      out = {'message': 'mariadb-dump not found in PATH! This is required to take a backup.', 'title': 'Message', 'indicator': 'red', 'raise_exception': 1, '__frappe_exc_id': '0fce035cbc9e50683f238dc6b12849bc576cfc1e3203bb90f44b79e0'}
  File "apps/frappe/frappe/__init__.py", line 519, in _raise_exception
    raise exc
      exc = ExecutableNotFound('mariadb-dump not found in PATH! This is required to take a backup.')
      inspect = <module 'inspect' from '/opt/homebrew/Cellar/python@3.11/3.11.11/Frameworks/Python.framework/Versions/3.11/lib/python3.11/inspect.py'>
      msg = 'mariadb-dump not found in PATH! This is required to take a backup.'
      out = {'message': 'mariadb-dump not found in PATH! This is required to take a backup.', 'title': 'Message', 'indicator': 'red', 'raise_exception': 1, '__frappe_exc_id': '0fce035cbc9e50683f238dc6b12849bc576cfc1e3203bb90f44b79e0'}
      raise_exception = <class 'frappe.exceptions.ExecutableNotFound'>
frappe.exceptions.ExecutableNotFound: mariadb-dump not found in PATH! This is required to take a backup.
Backup failed for Site erpnexxt.local. Database or site_config.json may be corrupted
Traceback with variables (most recent call last):
  File "apps/frappe/frappe/commands/site.py", line 854, in backup
    odb = scheduled_backup(
      context = {'sites': ['erpnexxt.local'], 'force': False, 'verbose': True, 'profile': False}
      with_files = False
      backup_path = None
      backup_path_db = None
      backup_path_files = None
      backup_path_private_files = None
      backup_path_conf = None
      ignore_backup_conf = False
      verbose = True
      compress = False
      include = ''
      exclude = ''
      old_backup_metadata = False
      scheduled_backup = <function scheduled_backup at 0x113674040>
      exit_code = 0
      rollback_callback = None
      site = 'erpnexxt.local'
  File "apps/frappe/frappe/utils/backups.py", line 568, in scheduled_backup
    return new_backup(
      older_than = 6
      ignore_files = True
      backup_path = None
      backup_path_db = None
      backup_path_files = None
      backup_path_private_files = None
      backup_path_conf = None
      ignore_conf = False
      include_doctypes = ''
      exclude_doctypes = ''
      compress = False
      force = True
      verbose = True
      old_backup_metadata = False
      rollback_callback = <frappe.utils.CallbackManager object at 0x1138bc1f0>
  File "apps/frappe/frappe/utils/backups.py", line 626, in new_backup
    odb.get_backup(older_than, ignore_files, force=force)
      older_than = 6
      ignore_files = True
      backup_path = None
      backup_path_db = None
      backup_path_files = None
      backup_path_private_files = None
      backup_path_conf = None
      ignore_conf = False
      include_doctypes = ''
      exclude_doctypes = ''
      compress = False
      force = True
      verbose = True
      old_backup_metadata = False
      rollback_callback = <frappe.utils.CallbackManager object at 0x1138bc1f0>
      odb = <frappe.utils.backups.BackupGenerator object at 0x1136e6b50>
  File "apps/frappe/frappe/utils/backups.py", line 195, in get_backup
    self.delete_if_step_fails(self.take_dump, self.backup_path_db)
      self = <frappe.utils.backups.BackupGenerator object at 0x1136e6b50>
      older_than = 6
      ignore_files = True
      force = True
      last_db = False
      last_file = False
      last_private_file = False
      site_config_backup_path = False
  File "apps/frappe/frappe/utils/backups.py", line 520, in delete_if_step_fails
    raise e
      self = <frappe.utils.backups.BackupGenerator object at 0x1136e6b50>
      step = <bound method BackupGenerator.take_dump of <frappe.utils.backups.BackupGenerator object at 0x1136e6b50>>
      paths = ('./erpnexxt.local/private/backups/20250211_000116-erpnexxt_local-database.sql.gz',)
      path = './erpnexxt.local/private/backups/20250211_000116-erpnexxt_local-database.sql.gz'
  File "apps/frappe/frappe/utils/backups.py", line 515, in delete_if_step_fails
    step()
      self = <frappe.utils.backups.BackupGenerator object at 0x1136e6b50>
      step = <bound method BackupGenerator.take_dump of <frappe.utils.backups.BackupGenerator object at 0x1136e6b50>>
      paths = ('./erpnexxt.local/private/backups/20250211_000116-erpnexxt_local-database.sql.gz',)
      path = './erpnexxt.local/private/backups/20250211_000116-erpnexxt_local-database.sql.gz'
  File "apps/frappe/frappe/utils/backups.py", line 457, in take_dump
    frappe.throw(
      self = <frappe.utils.backups.BackupGenerator object at 0x1136e6b50>
      shlex = <module 'shlex' from '/opt/homebrew/Cellar/python@3.11/3.11.11/Frameworks/Python.framework/Versions/3.11/lib/python3.11/shlex.py'>
      frappe = <module 'frappe' from 'apps/frappe/frappe/__init__.py'>
      get_app_branch = <function get_app_branch at 0x113647ce0>
      gzip_exc = '/usr/bin/gzip'
      database_header_content = ['begin frappe metadata', '[frappe]', 'version = 15.54.1', 'branch = version-15', 'end frappe metadata', '']
      generated_header = '-- begin frappe metadata\n-- [frappe]\n-- version = 15.54.1\n-- branch = version-15\n-- end frappe metadata\n-- \n'
      f = <_io.TextIOWrapper name='./erpnexxt.local/private/backups/20250211_000116-erpnexxt_local-database.sql.gz' encoding='UTF-8'>
      cmd = []
      extra = []
      get_command = <function get_command at 0x1136367a0>
      bin = None
      args = ['--user=_e7903427184a81b1', '--host=127.0.0.1', '--port=3306', '--password=eHVakHXsPB0Hhyx0', '--single-transaction', '--quick', '--lock-tables=false', '_e7903427184a81b1']
      bin_name = 'mariadb-dump'
  File "apps/frappe/frappe/__init__.py", line 603, in throw
    msgprint(
      msg = 'mariadb-dump not found in PATH! This is required to take a backup.'
      exc = <class 'frappe.exceptions.ExecutableNotFound'>
      title = None
      is_minimizable = False
      wide = False
      as_list = False
      primary_action = None
  File "apps/frappe/frappe/__init__.py", line 568, in msgprint
    _raise_exception()
      msg = 'mariadb-dump not found in PATH! This is required to take a backup.'
      title = None
      raise_exception = <class 'frappe.exceptions.ExecutableNotFound'>
      as_table = False
      as_list = False
      indicator = 'red'
      alert = False
      primary_action = None
      is_minimizable = False
      wide = False
      realtime = False
      sys = <module 'sys' (built-in)>
      _raise_exception = <function msgprint.<locals>._raise_exception at 0x110f01da0>
      inspect = <module 'inspect' from '/opt/homebrew/Cellar/python@3.11/3.11.11/Frameworks/Python.framework/Versions/3.11/lib/python3.11/inspect.py'>
      out = {'message': 'mariadb-dump not found in PATH! This is required to take a backup.', 'title': 'Message', 'indicator': 'red', 'raise_exception': 1, '__frappe_exc_id': '684cf00289e69f880d37b78cfe4a1f7905dfa3373a364012d34053ef'}
  File "apps/frappe/frappe/__init__.py", line 519, in _raise_exception
    raise exc
      exc = ExecutableNotFound('mariadb-dump not found in PATH! This is required to take a backup.')
      inspect = <module 'inspect' from '/opt/homebrew/Cellar/python@3.11/3.11.11/Frameworks/Python.framework/Versions/3.11/lib/python3.11/inspect.py'>
      msg = 'mariadb-dump not found in PATH! This is required to take a backup.'
      out = {'message': 'mariadb-dump not found in PATH! This is required to take a backup.', 'title': 'Message', 'indicator': 'red', 'raise_exception': 1, '__frappe_exc_id': '684cf00289e69f880d37b78cfe4a1f7905dfa3373a364012d34053ef'}
      raise_exception = <class 'frappe.exceptions.ExecutableNotFound'>
frappe.exceptions.ExecutableNotFound: mariadb-dump not found in PATH! This is required to take a backup.
Backup failed for Site erpnexxt.local. Database or site_config.json may be corrupted
Traceback with variables (most recent call last):
  File "apps/frappe/frappe/commands/site.py", line 854, in backup
    odb = scheduled_backup(
      context = {'sites': ['erpnexxt.local'], 'force': False, 'verbose': True, 'profile': False}
      with_files = False
      backup_path = None
      backup_path_db = None
      backup_path_files = None
      backup_path_private_files = None
      backup_path_conf = None
      ignore_backup_conf = False
      verbose = True
      compress = False
      include = ''
      exclude = ''
      old_backup_metadata = False
      scheduled_backup = <function scheduled_backup at 0x105930040>
      exit_code = 0
      rollback_callback = None
      site = 'erpnexxt.local'
  File "apps/frappe/frappe/utils/backups.py", line 568, in scheduled_backup
    return new_backup(
      older_than = 6
      ignore_files = True
      backup_path = None
      backup_path_db = None
      backup_path_files = None
      backup_path_private_files = None
      backup_path_conf = None
      ignore_conf = False
      include_doctypes = ''
      exclude_doctypes = ''
      compress = False
      force = True
      verbose = True
      old_backup_metadata = False
      rollback_callback = <frappe.utils.CallbackManager object at 0x105b781f0>
  File "apps/frappe/frappe/utils/backups.py", line 626, in new_backup
    odb.get_backup(older_than, ignore_files, force=force)
      older_than = 6
      ignore_files = True
      backup_path = None
      backup_path_db = None
      backup_path_files = None
      backup_path_private_files = None
      backup_path_conf = None
      ignore_conf = False
      include_doctypes = ''
      exclude_doctypes = ''
      compress = False
      force = True
      verbose = True
      old_backup_metadata = False
      rollback_callback = <frappe.utils.CallbackManager object at 0x105b781f0>
      odb = <frappe.utils.backups.BackupGenerator object at 0x1059a2e90>
  File "apps/frappe/frappe/utils/backups.py", line 195, in get_backup
    self.delete_if_step_fails(self.take_dump, self.backup_path_db)
      self = <frappe.utils.backups.BackupGenerator object at 0x1059a2e90>
      older_than = 6
      ignore_files = True
      force = True
      last_db = False
      last_file = False
      last_private_file = False
      site_config_backup_path = False
  File "apps/frappe/frappe/utils/backups.py", line 520, in delete_if_step_fails
    raise e
      self = <frappe.utils.backups.BackupGenerator object at 0x1059a2e90>
      step = <bound method BackupGenerator.take_dump of <frappe.utils.backups.BackupGenerator object at 0x1059a2e90>>
      paths = ('./erpnexxt.local/private/backups/20250211_180007-erpnexxt_local-database.sql.gz',)
      path = './erpnexxt.local/private/backups/20250211_180007-erpnexxt_local-database.sql.gz'
  File "apps/frappe/frappe/utils/backups.py", line 515, in delete_if_step_fails
    step()
      self = <frappe.utils.backups.BackupGenerator object at 0x1059a2e90>
      step = <bound method BackupGenerator.take_dump of <frappe.utils.backups.BackupGenerator object at 0x1059a2e90>>
      paths = ('./erpnexxt.local/private/backups/20250211_180007-erpnexxt_local-database.sql.gz',)
      path = './erpnexxt.local/private/backups/20250211_180007-erpnexxt_local-database.sql.gz'
  File "apps/frappe/frappe/utils/backups.py", line 457, in take_dump
    frappe.throw(
      self = <frappe.utils.backups.BackupGenerator object at 0x1059a2e90>
      shlex = <module 'shlex' from '/opt/homebrew/Cellar/python@3.11/3.11.11/Frameworks/Python.framework/Versions/3.11/lib/python3.11/shlex.py'>
      frappe = <module 'frappe' from 'apps/frappe/frappe/__init__.py'>
      get_app_branch = <function get_app_branch at 0x105903ce0>
      gzip_exc = '/usr/bin/gzip'
      database_header_content = ['begin frappe metadata', '[frappe]', 'version = 15.54.1', 'branch = version-15', 'end frappe metadata', '']
      generated_header = '-- begin frappe metadata\n-- [frappe]\n-- version = 15.54.1\n-- branch = version-15\n-- end frappe metadata\n-- \n'
      f = <_io.TextIOWrapper name='./erpnexxt.local/private/backups/20250211_180007-erpnexxt_local-database.sql.gz' encoding='UTF-8'>
      cmd = []
      extra = []
      get_command = <function get_command at 0x1058f27a0>
      bin = None
      args = ['--user=_e7903427184a81b1', '--host=127.0.0.1', '--port=3306', '--password=eHVakHXsPB0Hhyx0', '--single-transaction', '--quick', '--lock-tables=false', '_e7903427184a81b1']
      bin_name = 'mariadb-dump'
  File "apps/frappe/frappe/__init__.py", line 603, in throw
    msgprint(
      msg = 'mariadb-dump not found in PATH! This is required to take a backup.'
      exc = <class 'frappe.exceptions.ExecutableNotFound'>
      title = None
      is_minimizable = False
      wide = False
      as_list = False
      primary_action = None
  File "apps/frappe/frappe/__init__.py", line 568, in msgprint
    _raise_exception()
      msg = 'mariadb-dump not found in PATH! This is required to take a backup.'
      title = None
      raise_exception = <class 'frappe.exceptions.ExecutableNotFound'>
      as_table = False
      as_list = False
      indicator = 'red'
      alert = False
      primary_action = None
      is_minimizable = False
      wide = False
      realtime = False
      sys = <module 'sys' (built-in)>
      _raise_exception = <function msgprint.<locals>._raise_exception at 0x103cedda0>
      inspect = <module 'inspect' from '/opt/homebrew/Cellar/python@3.11/3.11.11/Frameworks/Python.framework/Versions/3.11/lib/python3.11/inspect.py'>
      out = {'message': 'mariadb-dump not found in PATH! This is required to take a backup.', 'title': 'Message', 'indicator': 'red', 'raise_exception': 1, '__frappe_exc_id': '63fb8a2e531e958f06bf0cdc46732a99b81565d325a67e9068d38ae7'}
  File "apps/frappe/frappe/__init__.py", line 519, in _raise_exception
    raise exc
      exc = ExecutableNotFound('mariadb-dump not found in PATH! This is required to take a backup.')
      inspect = <module 'inspect' from '/opt/homebrew/Cellar/python@3.11/3.11.11/Frameworks/Python.framework/Versions/3.11/lib/python3.11/inspect.py'>
      msg = 'mariadb-dump not found in PATH! This is required to take a backup.'
      out = {'message': 'mariadb-dump not found in PATH! This is required to take a backup.', 'title': 'Message', 'indicator': 'red', 'raise_exception': 1, '__frappe_exc_id': '63fb8a2e531e958f06bf0cdc46732a99b81565d325a67e9068d38ae7'}
      raise_exception = <class 'frappe.exceptions.ExecutableNotFound'>
frappe.exceptions.ExecutableNotFound: mariadb-dump not found in PATH! This is required to take a backup.
Backup failed for Site erpnexxt.local. Database or site_config.json may be corrupted
Traceback with variables (most recent call last):
  File "apps/frappe/frappe/commands/site.py", line 854, in backup
    odb = scheduled_backup(
      context = {'sites': ['erpnexxt.local'], 'force': False, 'verbose': True, 'profile': False}
      with_files = False
      backup_path = None
      backup_path_db = None
      backup_path_files = None
      backup_path_private_files = None
      backup_path_conf = None
      ignore_backup_conf = False
      verbose = True
      compress = False
      include = ''
      exclude = ''
      old_backup_metadata = False
      scheduled_backup = <function scheduled_backup at 0x104274040>
      exit_code = 0
      rollback_callback = None
      site = 'erpnexxt.local'
  File "apps/frappe/frappe/utils/backups.py", line 568, in scheduled_backup
    return new_backup(
      older_than = 6
      ignore_files = True
      backup_path = None
      backup_path_db = None
      backup_path_files = None
      backup_path_private_files = None
      backup_path_conf = None
      ignore_conf = False
      include_doctypes = ''
      exclude_doctypes = ''
      compress = False
      force = True
      verbose = True
      old_backup_metadata = False
      rollback_callback = <frappe.utils.CallbackManager object at 0x1044b84f0>
  File "apps/frappe/frappe/utils/backups.py", line 626, in new_backup
    odb.get_backup(older_than, ignore_files, force=force)
      older_than = 6
      ignore_files = True
      backup_path = None
      backup_path_db = None
      backup_path_files = None
      backup_path_private_files = None
      backup_path_conf = None
      ignore_conf = False
      include_doctypes = ''
      exclude_doctypes = ''
      compress = False
      force = True
      verbose = True
      old_backup_metadata = False
      rollback_callback = <frappe.utils.CallbackManager object at 0x1044b84f0>
      odb = <frappe.utils.backups.BackupGenerator object at 0x104499910>
  File "apps/frappe/frappe/utils/backups.py", line 195, in get_backup
    self.delete_if_step_fails(self.take_dump, self.backup_path_db)
      self = <frappe.utils.backups.BackupGenerator object at 0x104499910>
      older_than = 6
      ignore_files = True
      force = True
      last_db = False
      last_file = False
      last_private_file = False
      site_config_backup_path = False
  File "apps/frappe/frappe/utils/backups.py", line 520, in delete_if_step_fails
    raise e
      self = <frappe.utils.backups.BackupGenerator object at 0x104499910>
      step = <bound method BackupGenerator.take_dump of <frappe.utils.backups.BackupGenerator object at 0x104499910>>
      paths = ('./erpnexxt.local/private/backups/20250215_000008-erpnexxt_local-database.sql.gz',)
      path = './erpnexxt.local/private/backups/20250215_000008-erpnexxt_local-database.sql.gz'
  File "apps/frappe/frappe/utils/backups.py", line 515, in delete_if_step_fails
    step()
      self = <frappe.utils.backups.BackupGenerator object at 0x104499910>
      step = <bound method BackupGenerator.take_dump of <frappe.utils.backups.BackupGenerator object at 0x104499910>>
      paths = ('./erpnexxt.local/private/backups/20250215_000008-erpnexxt_local-database.sql.gz',)
      path = './erpnexxt.local/private/backups/20250215_000008-erpnexxt_local-database.sql.gz'
  File "apps/frappe/frappe/utils/backups.py", line 457, in take_dump
    frappe.throw(
      self = <frappe.utils.backups.BackupGenerator object at 0x104499910>
      shlex = <module 'shlex' from '/opt/homebrew/Cellar/python@3.11/3.11.11/Frameworks/Python.framework/Versions/3.11/lib/python3.11/shlex.py'>
      frappe = <module 'frappe' from 'apps/frappe/frappe/__init__.py'>
      get_app_branch = <function get_app_branch at 0x104247ce0>
      gzip_exc = '/usr/bin/gzip'
      database_header_content = ['begin frappe metadata', '[frappe]', 'version = 15.54.1', 'branch = version-15', 'end frappe metadata', '']
      generated_header = '-- begin frappe metadata\n-- [frappe]\n-- version = 15.54.1\n-- branch = version-15\n-- end frappe metadata\n-- \n'
      f = <_io.TextIOWrapper name='./erpnexxt.local/private/backups/20250215_000008-erpnexxt_local-database.sql.gz' encoding='UTF-8'>
      cmd = []
      extra = []
      get_command = <function get_command at 0x1042367a0>
      bin = None
      args = ['--user=_e7903427184a81b1', '--host=127.0.0.1', '--port=3306', '--password=eHVakHXsPB0Hhyx0', '--single-transaction', '--quick', '--lock-tables=false', '_e7903427184a81b1']
      bin_name = 'mariadb-dump'
  File "apps/frappe/frappe/__init__.py", line 603, in throw
    msgprint(
      msg = 'mariadb-dump not found in PATH! This is required to take a backup.'
      exc = <class 'frappe.exceptions.ExecutableNotFound'>
      title = None
      is_minimizable = False
      wide = False
      as_list = False
      primary_action = None
  File "apps/frappe/frappe/__init__.py", line 568, in msgprint
    _raise_exception()
      msg = 'mariadb-dump not found in PATH! This is required to take a backup.'
      title = None
      raise_exception = <class 'frappe.exceptions.ExecutableNotFound'>
      as_table = False
      as_list = False
      indicator = 'red'
      alert = False
      primary_action = None
      is_minimizable = False
      wide = False
      realtime = False
      sys = <module 'sys' (built-in)>
      _raise_exception = <function msgprint.<locals>._raise_exception at 0x104677740>
      inspect = <module 'inspect' from '/opt/homebrew/Cellar/python@3.11/3.11.11/Frameworks/Python.framework/Versions/3.11/lib/python3.11/inspect.py'>
      out = {'message': 'mariadb-dump not found in PATH! This is required to take a backup.', 'title': 'Message', 'indicator': 'red', 'raise_exception': 1, '__frappe_exc_id': 'e5c084178d9001983facb4fa564d1dc988b4fb7485b72260334517ee'}
  File "apps/frappe/frappe/__init__.py", line 519, in _raise_exception
    raise exc
      exc = ExecutableNotFound('mariadb-dump not found in PATH! This is required to take a backup.')
      inspect = <module 'inspect' from '/opt/homebrew/Cellar/python@3.11/3.11.11/Frameworks/Python.framework/Versions/3.11/lib/python3.11/inspect.py'>
      msg = 'mariadb-dump not found in PATH! This is required to take a backup.'
      out = {'message': 'mariadb-dump not found in PATH! This is required to take a backup.', 'title': 'Message', 'indicator': 'red', 'raise_exception': 1, '__frappe_exc_id': 'e5c084178d9001983facb4fa564d1dc988b4fb7485b72260334517ee'}
      raise_exception = <class 'frappe.exceptions.ExecutableNotFound'>
frappe.exceptions.ExecutableNotFound: mariadb-dump not found in PATH! This is required to take a backup.
Backup failed for Site erpnexxt.local. Database or site_config.json may be corrupted
Traceback with variables (most recent call last):
  File "apps/frappe/frappe/commands/site.py", line 854, in backup
    odb = scheduled_backup(
      context = {'sites': ['erpnexxt.local'], 'force': False, 'verbose': True, 'profile': False}
      with_files = False
      backup_path = None
      backup_path_db = None
      backup_path_files = None
      backup_path_private_files = None
      backup_path_conf = None
      ignore_backup_conf = False
      verbose = True
      compress = False
      include = ''
      exclude = ''
      old_backup_metadata = False
      scheduled_backup = <function scheduled_backup at 0x108174040>
      exit_code = 0
      rollback_callback = None
      site = 'erpnexxt.local'
  File "apps/frappe/frappe/utils/backups.py", line 568, in scheduled_backup
    return new_backup(
      older_than = 6
      ignore_files = True
      backup_path = None
      backup_path_db = None
      backup_path_files = None
      backup_path_private_files = None
      backup_path_conf = None
      ignore_conf = False
      include_doctypes = ''
      exclude_doctypes = ''
      compress = False
      force = True
      verbose = True
      old_backup_metadata = False
      rollback_callback = <frappe.utils.CallbackManager object at 0x1085b84f0>
  File "apps/frappe/frappe/utils/backups.py", line 626, in new_backup
    odb.get_backup(older_than, ignore_files, force=force)
      older_than = 6
      ignore_files = True
      backup_path = None
      backup_path_db = None
      backup_path_files = None
      backup_path_private_files = None
      backup_path_conf = None
      ignore_conf = False
      include_doctypes = ''
      exclude_doctypes = ''
      compress = False
      force = True
      verbose = True
      old_backup_metadata = False
      rollback_callback = <frappe.utils.CallbackManager object at 0x1085b84f0>
      odb = <frappe.utils.backups.BackupGenerator object at 0x1085998d0>
  File "apps/frappe/frappe/utils/backups.py", line 195, in get_backup
    self.delete_if_step_fails(self.take_dump, self.backup_path_db)
      self = <frappe.utils.backups.BackupGenerator object at 0x1085998d0>
      older_than = 6
      ignore_files = True
      force = True
      last_db = False
      last_file = False
      last_private_file = False
      site_config_backup_path = False
  File "apps/frappe/frappe/utils/backups.py", line 520, in delete_if_step_fails
    raise e
      self = <frappe.utils.backups.BackupGenerator object at 0x1085998d0>
      step = <bound method BackupGenerator.take_dump of <frappe.utils.backups.BackupGenerator object at 0x1085998d0>>
      paths = ('./erpnexxt.local/private/backups/20250217_000006-erpnexxt_local-database.sql.gz',)
      path = './erpnexxt.local/private/backups/20250217_000006-erpnexxt_local-database.sql.gz'
  File "apps/frappe/frappe/utils/backups.py", line 515, in delete_if_step_fails
    step()
      self = <frappe.utils.backups.BackupGenerator object at 0x1085998d0>
      step = <bound method BackupGenerator.take_dump of <frappe.utils.backups.BackupGenerator object at 0x1085998d0>>
      paths = ('./erpnexxt.local/private/backups/20250217_000006-erpnexxt_local-database.sql.gz',)
      path = './erpnexxt.local/private/backups/20250217_000006-erpnexxt_local-database.sql.gz'
  File "apps/frappe/frappe/utils/backups.py", line 457, in take_dump
    frappe.throw(
      self = <frappe.utils.backups.BackupGenerator object at 0x1085998d0>
      shlex = <module 'shlex' from '/opt/homebrew/Cellar/python@3.11/3.11.11/Frameworks/Python.framework/Versions/3.11/lib/python3.11/shlex.py'>
      frappe = <module 'frappe' from 'apps/frappe/frappe/__init__.py'>
      get_app_branch = <function get_app_branch at 0x108147ce0>
      gzip_exc = '/usr/bin/gzip'
      database_header_content = ['begin frappe metadata', '[frappe]', 'version = 15.54.1', 'branch = version-15', 'end frappe metadata', '']
      generated_header = '-- begin frappe metadata\n-- [frappe]\n-- version = 15.54.1\n-- branch = version-15\n-- end frappe metadata\n-- \n'
      f = <_io.TextIOWrapper name='./erpnexxt.local/private/backups/20250217_000006-erpnexxt_local-database.sql.gz' encoding='UTF-8'>
      cmd = []
      extra = []
      get_command = <function get_command at 0x1081367a0>
      bin = None
      args = ['--user=_e7903427184a81b1', '--host=127.0.0.1', '--port=3306', '--password=eHVakHXsPB0Hhyx0', '--single-transaction', '--quick', '--lock-tables=false', '_e7903427184a81b1']
      bin_name = 'mariadb-dump'
  File "apps/frappe/frappe/__init__.py", line 603, in throw
    msgprint(
      msg = 'mariadb-dump not found in PATH! This is required to take a backup.'
      exc = <class 'frappe.exceptions.ExecutableNotFound'>
      title = None
      is_minimizable = False
      wide = False
      as_list = False
      primary_action = None
  File "apps/frappe/frappe/__init__.py", line 568, in msgprint
    _raise_exception()
      msg = 'mariadb-dump not found in PATH! This is required to take a backup.'
      title = None
      raise_exception = <class 'frappe.exceptions.ExecutableNotFound'>
      as_table = False
      as_list = False
      indicator = 'red'
      alert = False
      primary_action = None
      is_minimizable = False
      wide = False
      realtime = False
      sys = <module 'sys' (built-in)>
      _raise_exception = <function msgprint.<locals>._raise_exception at 0x108777740>
      inspect = <module 'inspect' from '/opt/homebrew/Cellar/python@3.11/3.11.11/Frameworks/Python.framework/Versions/3.11/lib/python3.11/inspect.py'>
      out = {'message': 'mariadb-dump not found in PATH! This is required to take a backup.', 'title': 'Message', 'indicator': 'red', 'raise_exception': 1, '__frappe_exc_id': 'bd4aa1e6045348fe4ed34bc004c6b9fbd7ef632f7c1db0b3af82ecf8'}
  File "apps/frappe/frappe/__init__.py", line 519, in _raise_exception
    raise exc
      exc = ExecutableNotFound('mariadb-dump not found in PATH! This is required to take a backup.')
      inspect = <module 'inspect' from '/opt/homebrew/Cellar/python@3.11/3.11.11/Frameworks/Python.framework/Versions/3.11/lib/python3.11/inspect.py'>
      msg = 'mariadb-dump not found in PATH! This is required to take a backup.'
      out = {'message': 'mariadb-dump not found in PATH! This is required to take a backup.', 'title': 'Message', 'indicator': 'red', 'raise_exception': 1, '__frappe_exc_id': 'bd4aa1e6045348fe4ed34bc004c6b9fbd7ef632f7c1db0b3af82ecf8'}
      raise_exception = <class 'frappe.exceptions.ExecutableNotFound'>
frappe.exceptions.ExecutableNotFound: mariadb-dump not found in PATH! This is required to take a backup.
Backup failed for Site erpnexxt.local. Database or site_config.json may be corrupted
Traceback with variables (most recent call last):
  File "apps/frappe/frappe/commands/site.py", line 854, in backup
    odb = scheduled_backup(
      context = {'sites': ['erpnexxt.local'], 'force': False, 'verbose': True, 'profile': False}
      with_files = False
      backup_path = None
      backup_path_db = None
      backup_path_files = None
      backup_path_private_files = None
      backup_path_conf = None
      ignore_backup_conf = False
      verbose = True
      compress = False
      include = ''
      exclude = ''
      old_backup_metadata = False
      scheduled_backup = <function scheduled_backup at 0x106274040>
      exit_code = 0
      rollback_callback = None
      site = 'erpnexxt.local'
  File "apps/frappe/frappe/utils/backups.py", line 568, in scheduled_backup
    return new_backup(
      older_than = 6
      ignore_files = True
      backup_path = None
      backup_path_db = None
      backup_path_files = None
      backup_path_private_files = None
      backup_path_conf = None
      ignore_conf = False
      include_doctypes = ''
      exclude_doctypes = ''
      compress = False
      force = True
      verbose = True
      old_backup_metadata = False
      rollback_callback = <frappe.utils.CallbackManager object at 0x1066b84f0>
  File "apps/frappe/frappe/utils/backups.py", line 626, in new_backup
    odb.get_backup(older_than, ignore_files, force=force)
      older_than = 6
      ignore_files = True
      backup_path = None
      backup_path_db = None
      backup_path_files = None
      backup_path_private_files = None
      backup_path_conf = None
      ignore_conf = False
      include_doctypes = ''
      exclude_doctypes = ''
      compress = False
      force = True
      verbose = True
      old_backup_metadata = False
      rollback_callback = <frappe.utils.CallbackManager object at 0x1066b84f0>
      odb = <frappe.utils.backups.BackupGenerator object at 0x1066998d0>
  File "apps/frappe/frappe/utils/backups.py", line 195, in get_backup
    self.delete_if_step_fails(self.take_dump, self.backup_path_db)
      self = <frappe.utils.backups.BackupGenerator object at 0x1066998d0>
      older_than = 6
      ignore_files = True
      force = True
      last_db = False
      last_file = False
      last_private_file = False
      site_config_backup_path = False
  File "apps/frappe/frappe/utils/backups.py", line 520, in delete_if_step_fails
    raise e
      self = <frappe.utils.backups.BackupGenerator object at 0x1066998d0>
      step = <bound method BackupGenerator.take_dump of <frappe.utils.backups.BackupGenerator object at 0x1066998d0>>
      paths = ('./erpnexxt.local/private/backups/20250217_180006-erpnexxt_local-database.sql.gz',)
      path = './erpnexxt.local/private/backups/20250217_180006-erpnexxt_local-database.sql.gz'
  File "apps/frappe/frappe/utils/backups.py", line 515, in delete_if_step_fails
    step()
      self = <frappe.utils.backups.BackupGenerator object at 0x1066998d0>
      step = <bound method BackupGenerator.take_dump of <frappe.utils.backups.BackupGenerator object at 0x1066998d0>>
      paths = ('./erpnexxt.local/private/backups/20250217_180006-erpnexxt_local-database.sql.gz',)
      path = './erpnexxt.local/private/backups/20250217_180006-erpnexxt_local-database.sql.gz'
  File "apps/frappe/frappe/utils/backups.py", line 457, in take_dump
    frappe.throw(
      self = <frappe.utils.backups.BackupGenerator object at 0x1066998d0>
      shlex = <module 'shlex' from '/opt/homebrew/Cellar/python@3.11/3.11.11/Frameworks/Python.framework/Versions/3.11/lib/python3.11/shlex.py'>
      frappe = <module 'frappe' from 'apps/frappe/frappe/__init__.py'>
      get_app_branch = <function get_app_branch at 0x106247ce0>
      gzip_exc = '/usr/bin/gzip'
      database_header_content = ['begin frappe metadata', '[frappe]', 'version = 15.54.1', 'branch = version-15', 'end frappe metadata', '']
      generated_header = '-- begin frappe metadata\n-- [frappe]\n-- version = 15.54.1\n-- branch = version-15\n-- end frappe metadata\n-- \n'
      f = <_io.TextIOWrapper name='./erpnexxt.local/private/backups/20250217_180006-erpnexxt_local-database.sql.gz' encoding='UTF-8'>
      cmd = []
      extra = []
      get_command = <function get_command at 0x1062367a0>
      bin = None
      args = ['--user=_e7903427184a81b1', '--host=127.0.0.1', '--port=3306', '--password=eHVakHXsPB0Hhyx0', '--single-transaction', '--quick', '--lock-tables=false', '_e7903427184a81b1']
      bin_name = 'mariadb-dump'
  File "apps/frappe/frappe/__init__.py", line 603, in throw
    msgprint(
      msg = 'mariadb-dump not found in PATH! This is required to take a backup.'
      exc = <class 'frappe.exceptions.ExecutableNotFound'>
      title = None
      is_minimizable = False
      wide = False
      as_list = False
      primary_action = None
  File "apps/frappe/frappe/__init__.py", line 568, in msgprint
    _raise_exception()
      msg = 'mariadb-dump not found in PATH! This is required to take a backup.'
      title = None
      raise_exception = <class 'frappe.exceptions.ExecutableNotFound'>
      as_table = False
      as_list = False
      indicator = 'red'
      alert = False
      primary_action = None
      is_minimizable = False
      wide = False
      realtime = False
      sys = <module 'sys' (built-in)>
      _raise_exception = <function msgprint.<locals>._raise_exception at 0x106877740>
      inspect = <module 'inspect' from '/opt/homebrew/Cellar/python@3.11/3.11.11/Frameworks/Python.framework/Versions/3.11/lib/python3.11/inspect.py'>
      out = {'message': 'mariadb-dump not found in PATH! This is required to take a backup.', 'title': 'Message', 'indicator': 'red', 'raise_exception': 1, '__frappe_exc_id': '52775e5cb0b808eb03a29f44c2ef37d858472dcee3311a7b3c6957f6'}
  File "apps/frappe/frappe/__init__.py", line 519, in _raise_exception
    raise exc
      exc = ExecutableNotFound('mariadb-dump not found in PATH! This is required to take a backup.')
      inspect = <module 'inspect' from '/opt/homebrew/Cellar/python@3.11/3.11.11/Frameworks/Python.framework/Versions/3.11/lib/python3.11/inspect.py'>
      msg = 'mariadb-dump not found in PATH! This is required to take a backup.'
      out = {'message': 'mariadb-dump not found in PATH! This is required to take a backup.', 'title': 'Message', 'indicator': 'red', 'raise_exception': 1, '__frappe_exc_id': '52775e5cb0b808eb03a29f44c2ef37d858472dcee3311a7b3c6957f6'}
      raise_exception = <class 'frappe.exceptions.ExecutableNotFound'>
frappe.exceptions.ExecutableNotFound: mariadb-dump not found in PATH! This is required to take a backup.
Backup failed for Site erpnexxt.local. Database or site_config.json may be corrupted
Traceback with variables (most recent call last):
  File "apps/frappe/frappe/commands/site.py", line 854, in backup
    odb = scheduled_backup(
      context = {'sites': ['erpnexxt.local'], 'force': False, 'verbose': True, 'profile': False}
      with_files = False
      backup_path = None
      backup_path_db = None
      backup_path_files = None
      backup_path_private_files = None
      backup_path_conf = None
      ignore_backup_conf = False
      verbose = True
      compress = False
      include = ''
      exclude = ''
      old_backup_metadata = False
      scheduled_backup = <function scheduled_backup at 0x1063740e0>
      exit_code = 0
      rollback_callback = None
      site = 'erpnexxt.local'
  File "apps/frappe/frappe/utils/backups.py", line 568, in scheduled_backup
    return new_backup(
      older_than = 6
      ignore_files = True
      backup_path = None
      backup_path_db = None
      backup_path_files = None
      backup_path_private_files = None
      backup_path_conf = None
      ignore_conf = False
      include_doctypes = ''
      exclude_doctypes = ''
      compress = False
      force = True
      verbose = True
      old_backup_metadata = False
      rollback_callback = <frappe.utils.CallbackManager object at 0x1065b8640>
  File "apps/frappe/frappe/utils/backups.py", line 626, in new_backup
    odb.get_backup(older_than, ignore_files, force=force)
      older_than = 6
      ignore_files = True
      backup_path = None
      backup_path_db = None
      backup_path_files = None
      backup_path_private_files = None
      backup_path_conf = None
      ignore_conf = False
      include_doctypes = ''
      exclude_doctypes = ''
      compress = False
      force = True
      verbose = True
      old_backup_metadata = False
      rollback_callback = <frappe.utils.CallbackManager object at 0x1065b8640>
      odb = <frappe.utils.backups.BackupGenerator object at 0x10659a010>
  File "apps/frappe/frappe/utils/backups.py", line 195, in get_backup
    self.delete_if_step_fails(self.take_dump, self.backup_path_db)
      self = <frappe.utils.backups.BackupGenerator object at 0x10659a010>
      older_than = 6
      ignore_files = True
      force = True
      last_db = False
      last_file = False
      last_private_file = False
      site_config_backup_path = False
  File "apps/frappe/frappe/utils/backups.py", line 520, in delete_if_step_fails
    raise e
      self = <frappe.utils.backups.BackupGenerator object at 0x10659a010>
      step = <bound method BackupGenerator.take_dump of <frappe.utils.backups.BackupGenerator object at 0x10659a010>>
      paths = ('./erpnexxt.local/private/backups/20250218_060006-erpnexxt_local-database.sql.gz',)
      path = './erpnexxt.local/private/backups/20250218_060006-erpnexxt_local-database.sql.gz'
  File "apps/frappe/frappe/utils/backups.py", line 515, in delete_if_step_fails
    step()
      self = <frappe.utils.backups.BackupGenerator object at 0x10659a010>
      step = <bound method BackupGenerator.take_dump of <frappe.utils.backups.BackupGenerator object at 0x10659a010>>
      paths = ('./erpnexxt.local/private/backups/20250218_060006-erpnexxt_local-database.sql.gz',)
      path = './erpnexxt.local/private/backups/20250218_060006-erpnexxt_local-database.sql.gz'
  File "apps/frappe/frappe/utils/backups.py", line 457, in take_dump
    frappe.throw(
      self = <frappe.utils.backups.BackupGenerator object at 0x10659a010>
      shlex = <module 'shlex' from '/opt/homebrew/Cellar/python@3.11/3.11.11/Frameworks/Python.framework/Versions/3.11/lib/python3.11/shlex.py'>
      frappe = <module 'frappe' from 'apps/frappe/frappe/__init__.py'>
      get_app_branch = <function get_app_branch at 0x106347d80>
      gzip_exc = '/usr/bin/gzip'
      database_header_content = ['begin frappe metadata', '[frappe]', 'version = 15.56.0', 'branch = version-15', 'end frappe metadata', '']
      generated_header = '-- begin frappe metadata\n-- [frappe]\n-- version = 15.56.0\n-- branch = version-15\n-- end frappe metadata\n-- \n'
      f = <_io.TextIOWrapper name='./erpnexxt.local/private/backups/20250218_060006-erpnexxt_local-database.sql.gz' encoding='UTF-8'>
      cmd = []
      extra = []
      get_command = <function get_command at 0x106336840>
      bin = None
      args = ['--user=_e7903427184a81b1', '--host=127.0.0.1', '--port=3306', '--password=eHVakHXsPB0Hhyx0', '--single-transaction', '--quick', '--lock-tables=false', '_e7903427184a81b1']
      bin_name = 'mariadb-dump'
  File "apps/frappe/frappe/__init__.py", line 603, in throw
    msgprint(
      msg = 'mariadb-dump not found in PATH! This is required to take a backup.'
      exc = <class 'frappe.exceptions.ExecutableNotFound'>
      title = None
      is_minimizable = False
      wide = False
      as_list = False
      primary_action = None
  File "apps/frappe/frappe/__init__.py", line 568, in msgprint
    _raise_exception()
      msg = 'mariadb-dump not found in PATH! This is required to take a backup.'
      title = None
      raise_exception = <class 'frappe.exceptions.ExecutableNotFound'>
      as_table = False
      as_list = False
      indicator = 'red'
      alert = False
      primary_action = None
      is_minimizable = False
      wide = False
      realtime = False
      sys = <module 'sys' (built-in)>
      _raise_exception = <function msgprint.<locals>._raise_exception at 0x106777920>
      inspect = <module 'inspect' from '/opt/homebrew/Cellar/python@3.11/3.11.11/Frameworks/Python.framework/Versions/3.11/lib/python3.11/inspect.py'>
      out = {'message': 'mariadb-dump not found in PATH! This is required to take a backup.', 'title': 'Message', 'indicator': 'red', 'raise_exception': 1, '__frappe_exc_id': '099b391ccfb4cddb7096ea6cd02afd5d798901781321497d59c4d00f'}
  File "apps/frappe/frappe/__init__.py", line 519, in _raise_exception
    raise exc
      exc = ExecutableNotFound('mariadb-dump not found in PATH! This is required to take a backup.')
      inspect = <module 'inspect' from '/opt/homebrew/Cellar/python@3.11/3.11.11/Frameworks/Python.framework/Versions/3.11/lib/python3.11/inspect.py'>
      msg = 'mariadb-dump not found in PATH! This is required to take a backup.'
      out = {'message': 'mariadb-dump not found in PATH! This is required to take a backup.', 'title': 'Message', 'indicator': 'red', 'raise_exception': 1, '__frappe_exc_id': '099b391ccfb4cddb7096ea6cd02afd5d798901781321497d59c4d00f'}
      raise_exception = <class 'frappe.exceptions.ExecutableNotFound'>
frappe.exceptions.ExecutableNotFound: mariadb-dump not found in PATH! This is required to take a backup.
Backup failed for Site erpnexxt.local. Database or site_config.json may be corrupted
Traceback with variables (most recent call last):
  File "apps/frappe/frappe/commands/site.py", line 854, in backup
    odb = scheduled_backup(
      context = {'sites': ['erpnexxt.local'], 'force': False, 'verbose': True, 'profile': False}
      with_files = False
      backup_path = None
      backup_path_db = None
      backup_path_files = None
      backup_path_private_files = None
      backup_path_conf = None
      ignore_backup_conf = False
      verbose = True
      compress = False
      include = ''
      exclude = ''
      old_backup_metadata = False
      scheduled_backup = <function scheduled_backup at 0x1075740e0>
      exit_code = 0
      rollback_callback = None
      site = 'erpnexxt.local'
  File "apps/frappe/frappe/utils/backups.py", line 568, in scheduled_backup
    return new_backup(
      older_than = 6
      ignore_files = True
      backup_path = None
      backup_path_db = None
      backup_path_files = None
      backup_path_private_files = None
      backup_path_conf = None
      ignore_conf = False
      include_doctypes = ''
      exclude_doctypes = ''
      compress = False
      force = True
      verbose = True
      old_backup_metadata = False
      rollback_callback = <frappe.utils.CallbackManager object at 0x1100b8640>
  File "apps/frappe/frappe/utils/backups.py", line 626, in new_backup
    odb.get_backup(older_than, ignore_files, force=force)
      older_than = 6
      ignore_files = True
      backup_path = None
      backup_path_db = None
      backup_path_files = None
      backup_path_private_files = None
      backup_path_conf = None
      ignore_conf = False
      include_doctypes = ''
      exclude_doctypes = ''
      compress = False
      force = True
      verbose = True
      old_backup_metadata = False
      rollback_callback = <frappe.utils.CallbackManager object at 0x1100b8640>
      odb = <frappe.utils.backups.BackupGenerator object at 0x110099ed0>
  File "apps/frappe/frappe/utils/backups.py", line 195, in get_backup
    self.delete_if_step_fails(self.take_dump, self.backup_path_db)
      self = <frappe.utils.backups.BackupGenerator object at 0x110099ed0>
      older_than = 6
      ignore_files = True
      force = True
      last_db = False
      last_file = False
      last_private_file = False
      site_config_backup_path = False
  File "apps/frappe/frappe/utils/backups.py", line 520, in delete_if_step_fails
    raise e
      self = <frappe.utils.backups.BackupGenerator object at 0x110099ed0>
      step = <bound method BackupGenerator.take_dump of <frappe.utils.backups.BackupGenerator object at 0x110099ed0>>
      paths = ('./erpnexxt.local/private/backups/20250218_180043-erpnexxt_local-database.sql.gz',)
      path = './erpnexxt.local/private/backups/20250218_180043-erpnexxt_local-database.sql.gz'
  File "apps/frappe/frappe/utils/backups.py", line 515, in delete_if_step_fails
    step()
      self = <frappe.utils.backups.BackupGenerator object at 0x110099ed0>
      step = <bound method BackupGenerator.take_dump of <frappe.utils.backups.BackupGenerator object at 0x110099ed0>>
      paths = ('./erpnexxt.local/private/backups/20250218_180043-erpnexxt_local-database.sql.gz',)
      path = './erpnexxt.local/private/backups/20250218_180043-erpnexxt_local-database.sql.gz'
  File "apps/frappe/frappe/utils/backups.py", line 457, in take_dump
    frappe.throw(
      self = <frappe.utils.backups.BackupGenerator object at 0x110099ed0>
      shlex = <module 'shlex' from '/opt/homebrew/Cellar/python@3.11/3.11.11/Frameworks/Python.framework/Versions/3.11/lib/python3.11/shlex.py'>
      frappe = <module 'frappe' from 'apps/frappe/frappe/__init__.py'>
      get_app_branch = <function get_app_branch at 0x107547d80>
      gzip_exc = '/usr/bin/gzip'
      database_header_content = ['begin frappe metadata', '[frappe]', 'version = 15.56.0', 'branch = version-15', 'end frappe metadata', '']
      generated_header = '-- begin frappe metadata\n-- [frappe]\n-- version = 15.56.0\n-- branch = version-15\n-- end frappe metadata\n-- \n'
      f = <_io.TextIOWrapper name='./erpnexxt.local/private/backups/20250218_180043-erpnexxt_local-database.sql.gz' encoding='UTF-8'>
      cmd = []
      extra = []
      get_command = <function get_command at 0x107536840>
      bin = None
      args = ['--user=_e7903427184a81b1', '--host=127.0.0.1', '--port=3306', '--password=eHVakHXsPB0Hhyx0', '--single-transaction', '--quick', '--lock-tables=false', '_e7903427184a81b1']
      bin_name = 'mariadb-dump'
  File "apps/frappe/frappe/__init__.py", line 603, in throw
    msgprint(
      msg = 'mariadb-dump not found in PATH! This is required to take a backup.'
      exc = <class 'frappe.exceptions.ExecutableNotFound'>
      title = None
      is_minimizable = False
      wide = False
      as_list = False
      primary_action = None
  File "apps/frappe/frappe/__init__.py", line 568, in msgprint
    _raise_exception()
      msg = 'mariadb-dump not found in PATH! This is required to take a backup.'
      title = None
      raise_exception = <class 'frappe.exceptions.ExecutableNotFound'>
      as_table = False
      as_list = False
      indicator = 'red'
      alert = False
      primary_action = None
      is_minimizable = False
      wide = False
      realtime = False
      sys = <module 'sys' (built-in)>
      _raise_exception = <function msgprint.<locals>._raise_exception at 0x110377920>
      inspect = <module 'inspect' from '/opt/homebrew/Cellar/python@3.11/3.11.11/Frameworks/Python.framework/Versions/3.11/lib/python3.11/inspect.py'>
      out = {'message': 'mariadb-dump not found in PATH! This is required to take a backup.', 'title': 'Message', 'indicator': 'red', 'raise_exception': 1, '__frappe_exc_id': '189bf8b1c8f46765925244093925a546550c512458b636e10cb1fa17'}
  File "apps/frappe/frappe/__init__.py", line 519, in _raise_exception
    raise exc
      exc = ExecutableNotFound('mariadb-dump not found in PATH! This is required to take a backup.')
      inspect = <module 'inspect' from '/opt/homebrew/Cellar/python@3.11/3.11.11/Frameworks/Python.framework/Versions/3.11/lib/python3.11/inspect.py'>
      msg = 'mariadb-dump not found in PATH! This is required to take a backup.'
      out = {'message': 'mariadb-dump not found in PATH! This is required to take a backup.', 'title': 'Message', 'indicator': 'red', 'raise_exception': 1, '__frappe_exc_id': '189bf8b1c8f46765925244093925a546550c512458b636e10cb1fa17'}
      raise_exception = <class 'frappe.exceptions.ExecutableNotFound'>
frappe.exceptions.ExecutableNotFound: mariadb-dump not found in PATH! This is required to take a backup.
Backup failed for Site erpnexxt.local. Database or site_config.json may be corrupted
Traceback with variables (most recent call last):
  File "apps/frappe/frappe/commands/site.py", line 854, in backup
    odb = scheduled_backup(
      context = {'sites': ['erpnexxt.local'], 'force': False, 'verbose': True, 'profile': False}
      with_files = False
      backup_path = None
      backup_path_db = None
      backup_path_files = None
      backup_path_private_files = None
      backup_path_conf = None
      ignore_backup_conf = False
      verbose = True
      compress = False
      include = ''
      exclude = ''
      old_backup_metadata = False
      scheduled_backup = <function scheduled_backup at 0x10720c0e0>
      exit_code = 0
      rollback_callback = None
      site = 'erpnexxt.local'
  File "apps/frappe/frappe/utils/backups.py", line 568, in scheduled_backup
    return new_backup(
      older_than = 6
      ignore_files = True
      backup_path = None
      backup_path_db = None
      backup_path_files = None
      backup_path_private_files = None
      backup_path_conf = None
      ignore_conf = False
      include_doctypes = ''
      exclude_doctypes = ''
      compress = False
      force = True
      verbose = True
      old_backup_metadata = False
      rollback_callback = <frappe.utils.CallbackManager object at 0x107d08640>
  File "apps/frappe/frappe/utils/backups.py", line 626, in new_backup
    odb.get_backup(older_than, ignore_files, force=force)
      older_than = 6
      ignore_files = True
      backup_path = None
      backup_path_db = None
      backup_path_files = None
      backup_path_private_files = None
      backup_path_conf = None
      ignore_conf = False
      include_doctypes = ''
      exclude_doctypes = ''
      compress = False
      force = True
      verbose = True
      old_backup_metadata = False
      rollback_callback = <frappe.utils.CallbackManager object at 0x107d08640>
      odb = <frappe.utils.backups.BackupGenerator object at 0x107cea0d0>
  File "apps/frappe/frappe/utils/backups.py", line 195, in get_backup
    self.delete_if_step_fails(self.take_dump, self.backup_path_db)
      self = <frappe.utils.backups.BackupGenerator object at 0x107cea0d0>
      older_than = 6
      ignore_files = True
      force = True
      last_db = False
      last_file = False
      last_private_file = False
      site_config_backup_path = False
  File "apps/frappe/frappe/utils/backups.py", line 520, in delete_if_step_fails
    raise e
      self = <frappe.utils.backups.BackupGenerator object at 0x107cea0d0>
      step = <bound method BackupGenerator.take_dump of <frappe.utils.backups.BackupGenerator object at 0x107cea0d0>>
      paths = ('./erpnexxt.local/private/backups/20250220_000010-erpnexxt_local-database.sql.gz',)
      path = './erpnexxt.local/private/backups/20250220_000010-erpnexxt_local-database.sql.gz'
  File "apps/frappe/frappe/utils/backups.py", line 515, in delete_if_step_fails
    step()
      self = <frappe.utils.backups.BackupGenerator object at 0x107cea0d0>
      step = <bound method BackupGenerator.take_dump of <frappe.utils.backups.BackupGenerator object at 0x107cea0d0>>
      paths = ('./erpnexxt.local/private/backups/20250220_000010-erpnexxt_local-database.sql.gz',)
      path = './erpnexxt.local/private/backups/20250220_000010-erpnexxt_local-database.sql.gz'
  File "apps/frappe/frappe/utils/backups.py", line 457, in take_dump
    frappe.throw(
      self = <frappe.utils.backups.BackupGenerator object at 0x107cea0d0>
      shlex = <module 'shlex' from '/opt/homebrew/Cellar/python@3.11/3.11.11/Frameworks/Python.framework/Versions/3.11/lib/python3.11/shlex.py'>
      frappe = <module 'frappe' from 'apps/frappe/frappe/__init__.py'>
      get_app_branch = <function get_app_branch at 0x1071dfd80>
      gzip_exc = '/usr/bin/gzip'
      database_header_content = ['begin frappe metadata', '[frappe]', 'version = 15.56.0', 'branch = version-15', 'end frappe metadata', '']
      generated_header = '-- begin frappe metadata\n-- [frappe]\n-- version = 15.56.0\n-- branch = version-15\n-- end frappe metadata\n-- \n'
      f = <_io.TextIOWrapper name='./erpnexxt.local/private/backups/20250220_000010-erpnexxt_local-database.sql.gz' encoding='UTF-8'>
      cmd = []
      extra = []
      get_command = <function get_command at 0x1071ce840>
      bin = None
      args = ['--user=_e7903427184a81b1', '--host=127.0.0.1', '--port=3306', '--password=eHVakHXsPB0Hhyx0', '--single-transaction', '--quick', '--lock-tables=false', '_e7903427184a81b1']
      bin_name = 'mariadb-dump'
  File "apps/frappe/frappe/__init__.py", line 603, in throw
    msgprint(
      msg = 'mariadb-dump not found in PATH! This is required to take a backup.'
      exc = <class 'frappe.exceptions.ExecutableNotFound'>
      title = None
      is_minimizable = False
      wide = False
      as_list = False
      primary_action = None
  File "apps/frappe/frappe/__init__.py", line 568, in msgprint
    _raise_exception()
      msg = 'mariadb-dump not found in PATH! This is required to take a backup.'
      title = None
      raise_exception = <class 'frappe.exceptions.ExecutableNotFound'>
      as_table = False
      as_list = False
      indicator = 'red'
      alert = False
      primary_action = None
      is_minimizable = False
      wide = False
      realtime = False
      sys = <module 'sys' (built-in)>
      _raise_exception = <function msgprint.<locals>._raise_exception at 0x110477920>
      inspect = <module 'inspect' from '/opt/homebrew/Cellar/python@3.11/3.11.11/Frameworks/Python.framework/Versions/3.11/lib/python3.11/inspect.py'>
      out = {'message': 'mariadb-dump not found in PATH! This is required to take a backup.', 'title': 'Message', 'indicator': 'red', 'raise_exception': 1, '__frappe_exc_id': 'e7876704389f5c1f0938d86131568bd64f7a1aff3b16b3060e8f101f'}
  File "apps/frappe/frappe/__init__.py", line 519, in _raise_exception
    raise exc
      exc = ExecutableNotFound('mariadb-dump not found in PATH! This is required to take a backup.')
      inspect = <module 'inspect' from '/opt/homebrew/Cellar/python@3.11/3.11.11/Frameworks/Python.framework/Versions/3.11/lib/python3.11/inspect.py'>
      msg = 'mariadb-dump not found in PATH! This is required to take a backup.'
      out = {'message': 'mariadb-dump not found in PATH! This is required to take a backup.', 'title': 'Message', 'indicator': 'red', 'raise_exception': 1, '__frappe_exc_id': 'e7876704389f5c1f0938d86131568bd64f7a1aff3b16b3060e8f101f'}
      raise_exception = <class 'frappe.exceptions.ExecutableNotFound'>
frappe.exceptions.ExecutableNotFound: mariadb-dump not found in PATH! This is required to take a backup.
Backup failed for Site erpnexxt.local. Database or site_config.json may be corrupted
Traceback with variables (most recent call last):
  File "apps/frappe/frappe/commands/site.py", line 854, in backup
    odb = scheduled_backup(
      context = {'sites': ['erpnexxt.local'], 'force': False, 'verbose': True, 'profile': False}
      with_files = False
      backup_path = None
      backup_path_db = None
      backup_path_files = None
      backup_path_private_files = None
      backup_path_conf = None
      ignore_backup_conf = False
      verbose = True
      compress = False
      include = ''
      exclude = ''
      old_backup_metadata = False
      scheduled_backup = <function scheduled_backup at 0x1036b40e0>
      exit_code = 0
      rollback_callback = None
      site = 'erpnexxt.local'
  File "apps/frappe/frappe/utils/backups.py", line 568, in scheduled_backup
    return new_backup(
      older_than = 6
      ignore_files = True
      backup_path = None
      backup_path_db = None
      backup_path_files = None
      backup_path_private_files = None
      backup_path_conf = None
      ignore_conf = False
      include_doctypes = ''
      exclude_doctypes = ''
      compress = False
      force = True
      verbose = True
      old_backup_metadata = False
      rollback_callback = <frappe.utils.CallbackManager object at 0x1038f8640>
  File "apps/frappe/frappe/utils/backups.py", line 626, in new_backup
    odb.get_backup(older_than, ignore_files, force=force)
      older_than = 6
      ignore_files = True
      backup_path = None
      backup_path_db = None
      backup_path_files = None
      backup_path_private_files = None
      backup_path_conf = None
      ignore_conf = False
      include_doctypes = ''
      exclude_doctypes = ''
      compress = False
      force = True
      verbose = True
      old_backup_metadata = False
      rollback_callback = <frappe.utils.CallbackManager object at 0x1038f8640>
      odb = <frappe.utils.backups.BackupGenerator object at 0x1038da110>
  File "apps/frappe/frappe/utils/backups.py", line 195, in get_backup
    self.delete_if_step_fails(self.take_dump, self.backup_path_db)
      self = <frappe.utils.backups.BackupGenerator object at 0x1038da110>
      older_than = 6
      ignore_files = True
      force = True
      last_db = False
      last_file = False
      last_private_file = False
      site_config_backup_path = False
  File "apps/frappe/frappe/utils/backups.py", line 520, in delete_if_step_fails
    raise e
      self = <frappe.utils.backups.BackupGenerator object at 0x1038da110>
      step = <bound method BackupGenerator.take_dump of <frappe.utils.backups.BackupGenerator object at 0x1038da110>>
      paths = ('./erpnexxt.local/private/backups/20250220_180030-erpnexxt_local-database.sql.gz',)
      path = './erpnexxt.local/private/backups/20250220_180030-erpnexxt_local-database.sql.gz'
  File "apps/frappe/frappe/utils/backups.py", line 515, in delete_if_step_fails
    step()
      self = <frappe.utils.backups.BackupGenerator object at 0x1038da110>
      step = <bound method BackupGenerator.take_dump of <frappe.utils.backups.BackupGenerator object at 0x1038da110>>
      paths = ('./erpnexxt.local/private/backups/20250220_180030-erpnexxt_local-database.sql.gz',)
      path = './erpnexxt.local/private/backups/20250220_180030-erpnexxt_local-database.sql.gz'
  File "apps/frappe/frappe/utils/backups.py", line 457, in take_dump
    frappe.throw(
      self = <frappe.utils.backups.BackupGenerator object at 0x1038da110>
      shlex = <module 'shlex' from '/opt/homebrew/Cellar/python@3.11/3.11.11/Frameworks/Python.framework/Versions/3.11/lib/python3.11/shlex.py'>
      frappe = <module 'frappe' from 'apps/frappe/frappe/__init__.py'>
      get_app_branch = <function get_app_branch at 0x103687d80>
      gzip_exc = '/usr/bin/gzip'
      database_header_content = ['begin frappe metadata', '[frappe]', 'version = 15.56.0', 'branch = version-15', 'end frappe metadata', '']
      generated_header = '-- begin frappe metadata\n-- [frappe]\n-- version = 15.56.0\n-- branch = version-15\n-- end frappe metadata\n-- \n'
      f = <_io.TextIOWrapper name='./erpnexxt.local/private/backups/20250220_180030-erpnexxt_local-database.sql.gz' encoding='UTF-8'>
      cmd = []
      extra = []
      get_command = <function get_command at 0x103676840>
      bin = None
      args = ['--user=_e7903427184a81b1', '--host=127.0.0.1', '--port=3306', '--password=eHVakHXsPB0Hhyx0', '--single-transaction', '--quick', '--lock-tables=false', '_e7903427184a81b1']
      bin_name = 'mariadb-dump'
  File "apps/frappe/frappe/__init__.py", line 603, in throw
    msgprint(
      msg = 'mariadb-dump not found in PATH! This is required to take a backup.'
      exc = <class 'frappe.exceptions.ExecutableNotFound'>
      title = None
      is_minimizable = False
      wide = False
      as_list = False
      primary_action = None
  File "apps/frappe/frappe/__init__.py", line 568, in msgprint
    _raise_exception()
      msg = 'mariadb-dump not found in PATH! This is required to take a backup.'
      title = None
      raise_exception = <class 'frappe.exceptions.ExecutableNotFound'>
      as_table = False
      as_list = False
      indicator = 'red'
      alert = False
      primary_action = None
      is_minimizable = False
      wide = False
      realtime = False
      sys = <module 'sys' (built-in)>
      _raise_exception = <function msgprint.<locals>._raise_exception at 0x103ab7920>
      inspect = <module 'inspect' from '/opt/homebrew/Cellar/python@3.11/3.11.11/Frameworks/Python.framework/Versions/3.11/lib/python3.11/inspect.py'>
      out = {'message': 'mariadb-dump not found in PATH! This is required to take a backup.', 'title': 'Message', 'indicator': 'red', 'raise_exception': 1, '__frappe_exc_id': '12a46a05af5b84b1a58557d100b3f2165eb70e9abc2bfaefbd0f70ad'}
  File "apps/frappe/frappe/__init__.py", line 519, in _raise_exception
    raise exc
      exc = ExecutableNotFound('mariadb-dump not found in PATH! This is required to take a backup.')
      inspect = <module 'inspect' from '/opt/homebrew/Cellar/python@3.11/3.11.11/Frameworks/Python.framework/Versions/3.11/lib/python3.11/inspect.py'>
      msg = 'mariadb-dump not found in PATH! This is required to take a backup.'
      out = {'message': 'mariadb-dump not found in PATH! This is required to take a backup.', 'title': 'Message', 'indicator': 'red', 'raise_exception': 1, '__frappe_exc_id': '12a46a05af5b84b1a58557d100b3f2165eb70e9abc2bfaefbd0f70ad'}
      raise_exception = <class 'frappe.exceptions.ExecutableNotFound'>
frappe.exceptions.ExecutableNotFound: mariadb-dump not found in PATH! This is required to take a backup.
Backup failed for Site erpnexxt.local. Database or site_config.json may be corrupted
Traceback with variables (most recent call last):
  File "apps/frappe/frappe/commands/site.py", line 854, in backup
    odb = scheduled_backup(
      context = {'sites': ['erpnexxt.local'], 'force': False, 'verbose': True, 'profile': False}
      with_files = False
      backup_path = None
      backup_path_db = None
      backup_path_files = None
      backup_path_private_files = None
      backup_path_conf = None
      ignore_backup_conf = False
      verbose = True
      compress = False
      include = ''
      exclude = ''
      old_backup_metadata = False
      scheduled_backup = <function scheduled_backup at 0x1052540e0>
      exit_code = 0
      rollback_callback = None
      site = 'erpnexxt.local'
  File "apps/frappe/frappe/utils/backups.py", line 568, in scheduled_backup
    return new_backup(
      older_than = 6
      ignore_files = True
      backup_path = None
      backup_path_db = None
      backup_path_files = None
      backup_path_private_files = None
      backup_path_conf = None
      ignore_conf = False
      include_doctypes = ''
      exclude_doctypes = ''
      compress = False
      force = True
      verbose = True
      old_backup_metadata = False
      rollback_callback = <frappe.utils.CallbackManager object at 0x105498640>
  File "apps/frappe/frappe/utils/backups.py", line 626, in new_backup
    odb.get_backup(older_than, ignore_files, force=force)
      older_than = 6
      ignore_files = True
      backup_path = None
      backup_path_db = None
      backup_path_files = None
      backup_path_private_files = None
      backup_path_conf = None
      ignore_conf = False
      include_doctypes = ''
      exclude_doctypes = ''
      compress = False
      force = True
      verbose = True
      old_backup_metadata = False
      rollback_callback = <frappe.utils.CallbackManager object at 0x105498640>
      odb = <frappe.utils.backups.BackupGenerator object at 0x105479790>
  File "apps/frappe/frappe/utils/backups.py", line 195, in get_backup
    self.delete_if_step_fails(self.take_dump, self.backup_path_db)
      self = <frappe.utils.backups.BackupGenerator object at 0x105479790>
      older_than = 6
      ignore_files = True
      force = True
      last_db = False
      last_file = False
      last_private_file = False
      site_config_backup_path = False
  File "apps/frappe/frappe/utils/backups.py", line 520, in delete_if_step_fails
    raise e
      self = <frappe.utils.backups.BackupGenerator object at 0x105479790>
      step = <bound method BackupGenerator.take_dump of <frappe.utils.backups.BackupGenerator object at 0x105479790>>
      paths = ('./erpnexxt.local/private/backups/20250221_180007-erpnexxt_local-database.sql.gz',)
      path = './erpnexxt.local/private/backups/20250221_180007-erpnexxt_local-database.sql.gz'
  File "apps/frappe/frappe/utils/backups.py", line 515, in delete_if_step_fails
    step()
      self = <frappe.utils.backups.BackupGenerator object at 0x105479790>
      step = <bound method BackupGenerator.take_dump of <frappe.utils.backups.BackupGenerator object at 0x105479790>>
      paths = ('./erpnexxt.local/private/backups/20250221_180007-erpnexxt_local-database.sql.gz',)
      path = './erpnexxt.local/private/backups/20250221_180007-erpnexxt_local-database.sql.gz'
  File "apps/frappe/frappe/utils/backups.py", line 457, in take_dump
    frappe.throw(
      self = <frappe.utils.backups.BackupGenerator object at 0x105479790>
      shlex = <module 'shlex' from '/opt/homebrew/Cellar/python@3.11/3.11.11/Frameworks/Python.framework/Versions/3.11/lib/python3.11/shlex.py'>
      frappe = <module 'frappe' from 'apps/frappe/frappe/__init__.py'>
      get_app_branch = <function get_app_branch at 0x105227d80>
      gzip_exc = '/usr/bin/gzip'
      database_header_content = ['begin frappe metadata', '[frappe]', 'version = 15.56.0', 'branch = master', 'end frappe metadata', '']
      generated_header = '-- begin frappe metadata\n-- [frappe]\n-- version = 15.56.0\n-- branch = master\n-- end frappe metadata\n-- \n'
      f = <_io.TextIOWrapper name='./erpnexxt.local/private/backups/20250221_180007-erpnexxt_local-database.sql.gz' encoding='UTF-8'>
      cmd = []
      extra = []
      get_command = <function get_command at 0x105216840>
      bin = None
      args = ['--user=_e7903427184a81b1', '--host=127.0.0.1', '--port=3306', '--password=eHVakHXsPB0Hhyx0', '--single-transaction', '--quick', '--lock-tables=false', '_e7903427184a81b1']
      bin_name = 'mariadb-dump'
  File "apps/frappe/frappe/__init__.py", line 603, in throw
    msgprint(
      msg = 'mariadb-dump not found in PATH! This is required to take a backup.'
      exc = <class 'frappe.exceptions.ExecutableNotFound'>
      title = None
      is_minimizable = False
      wide = False
      as_list = False
      primary_action = None
  File "apps/frappe/frappe/__init__.py", line 568, in msgprint
    _raise_exception()
      msg = 'mariadb-dump not found in PATH! This is required to take a backup.'
      title = None
      raise_exception = <class 'frappe.exceptions.ExecutableNotFound'>
      as_table = False
      as_list = False
      indicator = 'red'
      alert = False
      primary_action = None
      is_minimizable = False
      wide = False
      realtime = False
      sys = <module 'sys' (built-in)>
      _raise_exception = <function msgprint.<locals>._raise_exception at 0x105657920>
      inspect = <module 'inspect' from '/opt/homebrew/Cellar/python@3.11/3.11.11/Frameworks/Python.framework/Versions/3.11/lib/python3.11/inspect.py'>
      out = {'message': 'mariadb-dump not found in PATH! This is required to take a backup.', 'title': 'Message', 'indicator': 'red', 'raise_exception': 1, '__frappe_exc_id': '6e78844c7284af8f160d0a5911951056dc7b4984a1e91e2a228d5f21'}
  File "apps/frappe/frappe/__init__.py", line 519, in _raise_exception
    raise exc
      exc = ExecutableNotFound('mariadb-dump not found in PATH! This is required to take a backup.')
      inspect = <module 'inspect' from '/opt/homebrew/Cellar/python@3.11/3.11.11/Frameworks/Python.framework/Versions/3.11/lib/python3.11/inspect.py'>
      msg = 'mariadb-dump not found in PATH! This is required to take a backup.'
      out = {'message': 'mariadb-dump not found in PATH! This is required to take a backup.', 'title': 'Message', 'indicator': 'red', 'raise_exception': 1, '__frappe_exc_id': '6e78844c7284af8f160d0a5911951056dc7b4984a1e91e2a228d5f21'}
      raise_exception = <class 'frappe.exceptions.ExecutableNotFound'>
frappe.exceptions.ExecutableNotFound: mariadb-dump not found in PATH! This is required to take a backup.
Backup failed for Site erpnexxt.local. Database or site_config.json may be corrupted
Traceback with variables (most recent call last):
  File "apps/frappe/frappe/commands/site.py", line 854, in backup
    odb = scheduled_backup(
      context = {'sites': ['erpnexxt.local'], 'force': False, 'verbose': True, 'profile': False}
      with_files = False
      backup_path = None
      backup_path_db = None
      backup_path_files = None
      backup_path_private_files = None
      backup_path_conf = None
      ignore_backup_conf = False
      verbose = True
      compress = False
      include = ''
      exclude = ''
      old_backup_metadata = False
      scheduled_backup = <function scheduled_backup at 0x1077a40e0>
      exit_code = 0
      rollback_callback = None
      site = 'erpnexxt.local'
  File "apps/frappe/frappe/utils/backups.py", line 568, in scheduled_backup
    return new_backup(
      older_than = 6
      ignore_files = True
      backup_path = None
      backup_path_db = None
      backup_path_files = None
      backup_path_private_files = None
      backup_path_conf = None
      ignore_conf = False
      include_doctypes = ''
      exclude_doctypes = ''
      compress = False
      force = True
      verbose = True
      old_backup_metadata = False
      rollback_callback = <frappe.utils.CallbackManager object at 0x1079e8640>
  File "apps/frappe/frappe/utils/backups.py", line 626, in new_backup
    odb.get_backup(older_than, ignore_files, force=force)
      older_than = 6
      ignore_files = True
      backup_path = None
      backup_path_db = None
      backup_path_files = None
      backup_path_private_files = None
      backup_path_conf = None
      ignore_conf = False
      include_doctypes = ''
      exclude_doctypes = ''
      compress = False
      force = True
      verbose = True
      old_backup_metadata = False
      rollback_callback = <frappe.utils.CallbackManager object at 0x1079e8640>
      odb = <frappe.utils.backups.BackupGenerator object at 0x107813310>
  File "apps/frappe/frappe/utils/backups.py", line 195, in get_backup
    self.delete_if_step_fails(self.take_dump, self.backup_path_db)
      self = <frappe.utils.backups.BackupGenerator object at 0x107813310>
      older_than = 6
      ignore_files = True
      force = True
      last_db = False
      last_file = False
      last_private_file = False
      site_config_backup_path = False
  File "apps/frappe/frappe/utils/backups.py", line 520, in delete_if_step_fails
    raise e
      self = <frappe.utils.backups.BackupGenerator object at 0x107813310>
      step = <bound method BackupGenerator.take_dump of <frappe.utils.backups.BackupGenerator object at 0x107813310>>
      paths = ('./erpnexxt.local/private/backups/20250222_000003-erpnexxt_local-database.sql.gz',)
      path = './erpnexxt.local/private/backups/20250222_000003-erpnexxt_local-database.sql.gz'
  File "apps/frappe/frappe/utils/backups.py", line 515, in delete_if_step_fails
    step()
      self = <frappe.utils.backups.BackupGenerator object at 0x107813310>
      step = <bound method BackupGenerator.take_dump of <frappe.utils.backups.BackupGenerator object at 0x107813310>>
      paths = ('./erpnexxt.local/private/backups/20250222_000003-erpnexxt_local-database.sql.gz',)
      path = './erpnexxt.local/private/backups/20250222_000003-erpnexxt_local-database.sql.gz'
  File "apps/frappe/frappe/utils/backups.py", line 457, in take_dump
    frappe.throw(
      self = <frappe.utils.backups.BackupGenerator object at 0x107813310>
      shlex = <module 'shlex' from '/opt/homebrew/Cellar/python@3.11/3.11.11/Frameworks/Python.framework/Versions/3.11/lib/python3.11/shlex.py'>
      frappe = <module 'frappe' from 'apps/frappe/frappe/__init__.py'>
      get_app_branch = <function get_app_branch at 0x107777d80>
      gzip_exc = '/usr/bin/gzip'
      database_header_content = ['begin frappe metadata', '[frappe]', 'version = 15.56.0', 'branch = master', 'end frappe metadata', '']
      generated_header = '-- begin frappe metadata\n-- [frappe]\n-- version = 15.56.0\n-- branch = master\n-- end frappe metadata\n-- \n'
      f = <_io.TextIOWrapper name='./erpnexxt.local/private/backups/20250222_000003-erpnexxt_local-database.sql.gz' encoding='UTF-8'>
      cmd = []
      extra = []
      get_command = <function get_command at 0x107766840>
      bin = None
      args = ['--user=_e7903427184a81b1', '--host=127.0.0.1', '--port=3306', '--password=eHVakHXsPB0Hhyx0', '--single-transaction', '--quick', '--lock-tables=false', '_e7903427184a81b1']
      bin_name = 'mariadb-dump'
  File "apps/frappe/frappe/__init__.py", line 603, in throw
    msgprint(
      msg = 'mariadb-dump not found in PATH! This is required to take a backup.'
      exc = <class 'frappe.exceptions.ExecutableNotFound'>
      title = None
      is_minimizable = False
      wide = False
      as_list = False
      primary_action = None
  File "apps/frappe/frappe/__init__.py", line 568, in msgprint
    _raise_exception()
      msg = 'mariadb-dump not found in PATH! This is required to take a backup.'
      title = None
      raise_exception = <class 'frappe.exceptions.ExecutableNotFound'>
      as_table = False
      as_list = False
      indicator = 'red'
      alert = False
      primary_action = None
      is_minimizable = False
      wide = False
      realtime = False
      sys = <module 'sys' (built-in)>
      _raise_exception = <function msgprint.<locals>._raise_exception at 0x107ba7920>
      inspect = <module 'inspect' from '/opt/homebrew/Cellar/python@3.11/3.11.11/Frameworks/Python.framework/Versions/3.11/lib/python3.11/inspect.py'>
      out = {'message': 'mariadb-dump not found in PATH! This is required to take a backup.', 'title': 'Message', 'indicator': 'red', 'raise_exception': 1, '__frappe_exc_id': 'd50195e82a9093ec7e58f22a07e7fb45bdabb611f08c34d44870b985'}
  File "apps/frappe/frappe/__init__.py", line 519, in _raise_exception
    raise exc
      exc = ExecutableNotFound('mariadb-dump not found in PATH! This is required to take a backup.')
      inspect = <module 'inspect' from '/opt/homebrew/Cellar/python@3.11/3.11.11/Frameworks/Python.framework/Versions/3.11/lib/python3.11/inspect.py'>
      msg = 'mariadb-dump not found in PATH! This is required to take a backup.'
      out = {'message': 'mariadb-dump not found in PATH! This is required to take a backup.', 'title': 'Message', 'indicator': 'red', 'raise_exception': 1, '__frappe_exc_id': 'd50195e82a9093ec7e58f22a07e7fb45bdabb611f08c34d44870b985'}
      raise_exception = <class 'frappe.exceptions.ExecutableNotFound'>
frappe.exceptions.ExecutableNotFound: mariadb-dump not found in PATH! This is required to take a backup.
Backup failed for Site erpnexxt.local. Database or site_config.json may be corrupted
Traceback with variables (most recent call last):
  File "apps/frappe/frappe/commands/site.py", line 854, in backup
    odb = scheduled_backup(
      context = {'sites': ['erpnexxt.local'], 'force': False, 'verbose': True, 'profile': False}
      with_files = False
      backup_path = None
      backup_path_db = None
      backup_path_files = None
      backup_path_private_files = None
      backup_path_conf = None
      ignore_backup_conf = False
      verbose = True
      compress = False
      include = ''
      exclude = ''
      old_backup_metadata = False
      scheduled_backup = <function scheduled_backup at 0x1061740e0>
      exit_code = 0
      rollback_callback = None
      site = 'erpnexxt.local'
  File "apps/frappe/frappe/utils/backups.py", line 568, in scheduled_backup
    return new_backup(
      older_than = 6
      ignore_files = True
      backup_path = None
      backup_path_db = None
      backup_path_files = None
      backup_path_private_files = None
      backup_path_conf = None
      ignore_conf = False
      include_doctypes = ''
      exclude_doctypes = ''
      compress = False
      force = True
      verbose = True
      old_backup_metadata = False
      rollback_callback = <frappe.utils.CallbackManager object at 0x1064b8640>
  File "apps/frappe/frappe/utils/backups.py", line 626, in new_backup
    odb.get_backup(older_than, ignore_files, force=force)
      older_than = 6
      ignore_files = True
      backup_path = None
      backup_path_db = None
      backup_path_files = None
      backup_path_private_files = None
      backup_path_conf = None
      ignore_conf = False
      include_doctypes = ''
      exclude_doctypes = ''
      compress = False
      force = True
      verbose = True
      old_backup_metadata = False
      rollback_callback = <frappe.utils.CallbackManager object at 0x1064b8640>
      odb = <frappe.utils.backups.BackupGenerator object at 0x106499ed0>
  File "apps/frappe/frappe/utils/backups.py", line 195, in get_backup
    self.delete_if_step_fails(self.take_dump, self.backup_path_db)
      self = <frappe.utils.backups.BackupGenerator object at 0x106499ed0>
      older_than = 6
      ignore_files = True
      force = True
      last_db = False
      last_file = False
      last_private_file = False
      site_config_backup_path = False
  File "apps/frappe/frappe/utils/backups.py", line 520, in delete_if_step_fails
    raise e
      self = <frappe.utils.backups.BackupGenerator object at 0x106499ed0>
      step = <bound method BackupGenerator.take_dump of <frappe.utils.backups.BackupGenerator object at 0x106499ed0>>
      paths = ('./erpnexxt.local/private/backups/20250223_060003-erpnexxt_local-database.sql.gz',)
      path = './erpnexxt.local/private/backups/20250223_060003-erpnexxt_local-database.sql.gz'
  File "apps/frappe/frappe/utils/backups.py", line 515, in delete_if_step_fails
    step()
      self = <frappe.utils.backups.BackupGenerator object at 0x106499ed0>
      step = <bound method BackupGenerator.take_dump of <frappe.utils.backups.BackupGenerator object at 0x106499ed0>>
      paths = ('./erpnexxt.local/private/backups/20250223_060003-erpnexxt_local-database.sql.gz',)
      path = './erpnexxt.local/private/backups/20250223_060003-erpnexxt_local-database.sql.gz'
  File "apps/frappe/frappe/utils/backups.py", line 457, in take_dump
    frappe.throw(
      self = <frappe.utils.backups.BackupGenerator object at 0x106499ed0>
      shlex = <module 'shlex' from '/opt/homebrew/Cellar/python@3.11/3.11.11/Frameworks/Python.framework/Versions/3.11/lib/python3.11/shlex.py'>
      frappe = <module 'frappe' from 'apps/frappe/frappe/__init__.py'>
      get_app_branch = <function get_app_branch at 0x106147d80>
      gzip_exc = '/usr/bin/gzip'
      database_header_content = ['begin frappe metadata', '[frappe]', 'version = 15.56.0', 'branch = master', 'end frappe metadata', '']
      generated_header = '-- begin frappe metadata\n-- [frappe]\n-- version = 15.56.0\n-- branch = master\n-- end frappe metadata\n-- \n'
      f = <_io.TextIOWrapper name='./erpnexxt.local/private/backups/20250223_060003-erpnexxt_local-database.sql.gz' encoding='UTF-8'>
      cmd = []
      extra = []
      get_command = <function get_command at 0x106136840>
      bin = None
      args = ['--user=_e7903427184a81b1', '--host=127.0.0.1', '--port=3306', '--password=eHVakHXsPB0Hhyx0', '--single-transaction', '--quick', '--lock-tables=false', '_e7903427184a81b1']
      bin_name = 'mariadb-dump'
  File "apps/frappe/frappe/__init__.py", line 603, in throw
    msgprint(
      msg = 'mariadb-dump not found in PATH! This is required to take a backup.'
      exc = <class 'frappe.exceptions.ExecutableNotFound'>
      title = None
      is_minimizable = False
      wide = False
      as_list = False
      primary_action = None
  File "apps/frappe/frappe/__init__.py", line 568, in msgprint
    _raise_exception()
      msg = 'mariadb-dump not found in PATH! This is required to take a backup.'
      title = None
      raise_exception = <class 'frappe.exceptions.ExecutableNotFound'>
      as_table = False
      as_list = False
      indicator = 'red'
      alert = False
      primary_action = None
      is_minimizable = False
      wide = False
      realtime = False
      sys = <module 'sys' (built-in)>
      _raise_exception = <function msgprint.<locals>._raise_exception at 0x106677920>
      inspect = <module 'inspect' from '/opt/homebrew/Cellar/python@3.11/3.11.11/Frameworks/Python.framework/Versions/3.11/lib/python3.11/inspect.py'>
      out = {'message': 'mariadb-dump not found in PATH! This is required to take a backup.', 'title': 'Message', 'indicator': 'red', 'raise_exception': 1, '__frappe_exc_id': '047937e33608997bdfc5472b267c28af9db2b108e9b5c4a5ffbb5008'}
  File "apps/frappe/frappe/__init__.py", line 519, in _raise_exception
    raise exc
      exc = ExecutableNotFound('mariadb-dump not found in PATH! This is required to take a backup.')
      inspect = <module 'inspect' from '/opt/homebrew/Cellar/python@3.11/3.11.11/Frameworks/Python.framework/Versions/3.11/lib/python3.11/inspect.py'>
      msg = 'mariadb-dump not found in PATH! This is required to take a backup.'
      out = {'message': 'mariadb-dump not found in PATH! This is required to take a backup.', 'title': 'Message', 'indicator': 'red', 'raise_exception': 1, '__frappe_exc_id': '047937e33608997bdfc5472b267c28af9db2b108e9b5c4a5ffbb5008'}
      raise_exception = <class 'frappe.exceptions.ExecutableNotFound'>
frappe.exceptions.ExecutableNotFound: mariadb-dump not found in PATH! This is required to take a backup.
Backup failed for Site erpnexxt.local. Database or site_config.json may be corrupted
Traceback with variables (most recent call last):
  File "apps/frappe/frappe/commands/site.py", line 854, in backup
    odb = scheduled_backup(
      context = {'sites': ['erpnexxt.local'], 'force': False, 'verbose': True, 'profile': False}
      with_files = False
      backup_path = None
      backup_path_db = None
      backup_path_files = None
      backup_path_private_files = None
      backup_path_conf = None
      ignore_backup_conf = False
      verbose = True
      compress = False
      include = ''
      exclude = ''
      old_backup_metadata = False
      scheduled_backup = <function scheduled_backup at 0x1055500e0>
      exit_code = 0
      rollback_callback = None
      site = 'erpnexxt.local'
  File "apps/frappe/frappe/utils/backups.py", line 568, in scheduled_backup
    return new_backup(
      older_than = 6
      ignore_files = True
      backup_path = None
      backup_path_db = None
      backup_path_files = None
      backup_path_private_files = None
      backup_path_conf = None
      ignore_conf = False
      include_doctypes = ''
      exclude_doctypes = ''
      compress = False
      force = True
      verbose = True
      old_backup_metadata = False
      rollback_callback = <frappe.utils.CallbackManager object at 0x105794640>
  File "apps/frappe/frappe/utils/backups.py", line 626, in new_backup
    odb.get_backup(older_than, ignore_files, force=force)
      older_than = 6
      ignore_files = True
      backup_path = None
      backup_path_db = None
      backup_path_files = None
      backup_path_private_files = None
      backup_path_conf = None
      ignore_conf = False
      include_doctypes = ''
      exclude_doctypes = ''
      compress = False
      force = True
      verbose = True
      old_backup_metadata = False
      rollback_callback = <frappe.utils.CallbackManager object at 0x105794640>
      odb = <frappe.utils.backups.BackupGenerator object at 0x105775510>
  File "apps/frappe/frappe/utils/backups.py", line 195, in get_backup
    self.delete_if_step_fails(self.take_dump, self.backup_path_db)
      self = <frappe.utils.backups.BackupGenerator object at 0x105775510>
      older_than = 6
      ignore_files = True
      force = True
      last_db = False
      last_file = False
      last_private_file = False
      site_config_backup_path = False
  File "apps/frappe/frappe/utils/backups.py", line 520, in delete_if_step_fails
    raise e
      self = <frappe.utils.backups.BackupGenerator object at 0x105775510>
      step = <bound method BackupGenerator.take_dump of <frappe.utils.backups.BackupGenerator object at 0x105775510>>
      paths = ('./erpnexxt.local/private/backups/20250224_000005-erpnexxt_local-database.sql.gz',)
      path = './erpnexxt.local/private/backups/20250224_000005-erpnexxt_local-database.sql.gz'
  File "apps/frappe/frappe/utils/backups.py", line 515, in delete_if_step_fails
    step()
      self = <frappe.utils.backups.BackupGenerator object at 0x105775510>
      step = <bound method BackupGenerator.take_dump of <frappe.utils.backups.BackupGenerator object at 0x105775510>>
      paths = ('./erpnexxt.local/private/backups/20250224_000005-erpnexxt_local-database.sql.gz',)
      path = './erpnexxt.local/private/backups/20250224_000005-erpnexxt_local-database.sql.gz'
  File "apps/frappe/frappe/utils/backups.py", line 457, in take_dump
    frappe.throw(
      self = <frappe.utils.backups.BackupGenerator object at 0x105775510>
      shlex = <module 'shlex' from '/opt/homebrew/Cellar/python@3.11/3.11.11/Frameworks/Python.framework/Versions/3.11/lib/python3.11/shlex.py'>
      frappe = <module 'frappe' from 'apps/frappe/frappe/__init__.py'>
      get_app_branch = <function get_app_branch at 0x105523d80>
      gzip_exc = '/usr/bin/gzip'
      database_header_content = ['begin frappe metadata', '[frappe]', 'version = 15.56.0', 'branch = master', 'end frappe metadata', '']
      generated_header = '-- begin frappe metadata\n-- [frappe]\n-- version = 15.56.0\n-- branch = master\n-- end frappe metadata\n-- \n'
      f = <_io.TextIOWrapper name='./erpnexxt.local/private/backups/20250224_000005-erpnexxt_local-database.sql.gz' encoding='UTF-8'>
      cmd = []
      extra = []
      get_command = <function get_command at 0x105512840>
      bin = None
      args = ['--user=_e7903427184a81b1', '--host=127.0.0.1', '--port=3306', '--password=eHVakHXsPB0Hhyx0', '--single-transaction', '--quick', '--lock-tables=false', '_e7903427184a81b1']
      bin_name = 'mariadb-dump'
  File "apps/frappe/frappe/__init__.py", line 603, in throw
    msgprint(
      msg = 'mariadb-dump not found in PATH! This is required to take a backup.'
      exc = <class 'frappe.exceptions.ExecutableNotFound'>
      title = None
      is_minimizable = False
      wide = False
      as_list = False
      primary_action = None
  File "apps/frappe/frappe/__init__.py", line 568, in msgprint
    _raise_exception()
      msg = 'mariadb-dump not found in PATH! This is required to take a backup.'
      title = None
      raise_exception = <class 'frappe.exceptions.ExecutableNotFound'>
      as_table = False
      as_list = False
      indicator = 'red'
      alert = False
      primary_action = None
      is_minimizable = False
      wide = False
      realtime = False
      sys = <module 'sys' (built-in)>
      _raise_exception = <function msgprint.<locals>._raise_exception at 0x105a77920>
      inspect = <module 'inspect' from '/opt/homebrew/Cellar/python@3.11/3.11.11/Frameworks/Python.framework/Versions/3.11/lib/python3.11/inspect.py'>
      out = {'message': 'mariadb-dump not found in PATH! This is required to take a backup.', 'title': 'Message', 'indicator': 'red', 'raise_exception': 1, '__frappe_exc_id': '058a06888b9b7652aa8d22a1a668b57ce10e795d5a7d54decaad506f'}
  File "apps/frappe/frappe/__init__.py", line 519, in _raise_exception
    raise exc
      exc = ExecutableNotFound('mariadb-dump not found in PATH! This is required to take a backup.')
      inspect = <module 'inspect' from '/opt/homebrew/Cellar/python@3.11/3.11.11/Frameworks/Python.framework/Versions/3.11/lib/python3.11/inspect.py'>
      msg = 'mariadb-dump not found in PATH! This is required to take a backup.'
      out = {'message': 'mariadb-dump not found in PATH! This is required to take a backup.', 'title': 'Message', 'indicator': 'red', 'raise_exception': 1, '__frappe_exc_id': '058a06888b9b7652aa8d22a1a668b57ce10e795d5a7d54decaad506f'}
      raise_exception = <class 'frappe.exceptions.ExecutableNotFound'>
frappe.exceptions.ExecutableNotFound: mariadb-dump not found in PATH! This is required to take a backup.
Backup failed for Site erpnexxt.local. Database or site_config.json may be corrupted
Traceback with variables (most recent call last):
  File "apps/frappe/frappe/commands/site.py", line 854, in backup
    odb = scheduled_backup(
      context = {'sites': ['erpnexxt.local'], 'force': False, 'verbose': True, 'profile': False}
      with_files = False
      backup_path = None
      backup_path_db = None
      backup_path_files = None
      backup_path_private_files = None
      backup_path_conf = None
      ignore_backup_conf = False
      verbose = True
      compress = False
      include = ''
      exclude = ''
      old_backup_metadata = False
      scheduled_backup = <function scheduled_backup at 0x103b500e0>
      exit_code = 0
      rollback_callback = None
      site = 'erpnexxt.local'
  File "apps/frappe/frappe/utils/backups.py", line 568, in scheduled_backup
    return new_backup(
      older_than = 6
      ignore_files = True
      backup_path = None
      backup_path_db = None
      backup_path_files = None
      backup_path_private_files = None
      backup_path_conf = None
      ignore_conf = False
      include_doctypes = ''
      exclude_doctypes = ''
      compress = False
      force = True
      verbose = True
      old_backup_metadata = False
      rollback_callback = <frappe.utils.CallbackManager object at 0x103eb8640>
  File "apps/frappe/frappe/utils/backups.py", line 626, in new_backup
    odb.get_backup(older_than, ignore_files, force=force)
      older_than = 6
      ignore_files = True
      backup_path = None
      backup_path_db = None
      backup_path_files = None
      backup_path_private_files = None
      backup_path_conf = None
      ignore_conf = False
      include_doctypes = ''
      exclude_doctypes = ''
      compress = False
      force = True
      verbose = True
      old_backup_metadata = False
      rollback_callback = <frappe.utils.CallbackManager object at 0x103eb8640>
      odb = <frappe.utils.backups.BackupGenerator object at 0x103e9a010>
  File "apps/frappe/frappe/utils/backups.py", line 195, in get_backup
    self.delete_if_step_fails(self.take_dump, self.backup_path_db)
      self = <frappe.utils.backups.BackupGenerator object at 0x103e9a010>
      older_than = 6
      ignore_files = True
      force = True
      last_db = False
      last_file = False
      last_private_file = False
      site_config_backup_path = False
  File "apps/frappe/frappe/utils/backups.py", line 520, in delete_if_step_fails
    raise e
      self = <frappe.utils.backups.BackupGenerator object at 0x103e9a010>
      step = <bound method BackupGenerator.take_dump of <frappe.utils.backups.BackupGenerator object at 0x103e9a010>>
      paths = ('./erpnexxt.local/private/backups/20250224_060006-erpnexxt_local-database.sql.gz',)
      path = './erpnexxt.local/private/backups/20250224_060006-erpnexxt_local-database.sql.gz'
  File "apps/frappe/frappe/utils/backups.py", line 515, in delete_if_step_fails
    step()
      self = <frappe.utils.backups.BackupGenerator object at 0x103e9a010>
      step = <bound method BackupGenerator.take_dump of <frappe.utils.backups.BackupGenerator object at 0x103e9a010>>
      paths = ('./erpnexxt.local/private/backups/20250224_060006-erpnexxt_local-database.sql.gz',)
      path = './erpnexxt.local/private/backups/20250224_060006-erpnexxt_local-database.sql.gz'
  File "apps/frappe/frappe/utils/backups.py", line 457, in take_dump
    frappe.throw(
      self = <frappe.utils.backups.BackupGenerator object at 0x103e9a010>
      shlex = <module 'shlex' from '/opt/homebrew/Cellar/python@3.11/3.11.11/Frameworks/Python.framework/Versions/3.11/lib/python3.11/shlex.py'>
      frappe = <module 'frappe' from 'apps/frappe/frappe/__init__.py'>
      get_app_branch = <function get_app_branch at 0x103b23d80>
      gzip_exc = '/usr/bin/gzip'
      database_header_content = ['begin frappe metadata', '[frappe]', 'version = 15.56.0', 'branch = master', 'end frappe metadata', '']
      generated_header = '-- begin frappe metadata\n-- [frappe]\n-- version = 15.56.0\n-- branch = master\n-- end frappe metadata\n-- \n'
      f = <_io.TextIOWrapper name='./erpnexxt.local/private/backups/20250224_060006-erpnexxt_local-database.sql.gz' encoding='UTF-8'>
      cmd = []
      extra = []
      get_command = <function get_command at 0x103b12840>
      bin = None
      args = ['--user=_e7903427184a81b1', '--host=127.0.0.1', '--port=3306', '--password=eHVakHXsPB0Hhyx0', '--single-transaction', '--quick', '--lock-tables=false', '_e7903427184a81b1']
      bin_name = 'mariadb-dump'
  File "apps/frappe/frappe/__init__.py", line 603, in throw
    msgprint(
      msg = 'mariadb-dump not found in PATH! This is required to take a backup.'
      exc = <class 'frappe.exceptions.ExecutableNotFound'>
      title = None
      is_minimizable = False
      wide = False
      as_list = False
      primary_action = None
  File "apps/frappe/frappe/__init__.py", line 568, in msgprint
    _raise_exception()
      msg = 'mariadb-dump not found in PATH! This is required to take a backup.'
      title = None
      raise_exception = <class 'frappe.exceptions.ExecutableNotFound'>
      as_table = False
      as_list = False
      indicator = 'red'
      alert = False
      primary_action = None
      is_minimizable = False
      wide = False
      realtime = False
      sys = <module 'sys' (built-in)>
      _raise_exception = <function msgprint.<locals>._raise_exception at 0x104077920>
      inspect = <module 'inspect' from '/opt/homebrew/Cellar/python@3.11/3.11.11/Frameworks/Python.framework/Versions/3.11/lib/python3.11/inspect.py'>
      out = {'message': 'mariadb-dump not found in PATH! This is required to take a backup.', 'title': 'Message', 'indicator': 'red', 'raise_exception': 1, '__frappe_exc_id': '7d64db905e167e15cf1424ca29f7b3b6d2942b1233df49028a935f72'}
  File "apps/frappe/frappe/__init__.py", line 519, in _raise_exception
    raise exc
      exc = ExecutableNotFound('mariadb-dump not found in PATH! This is required to take a backup.')
      inspect = <module 'inspect' from '/opt/homebrew/Cellar/python@3.11/3.11.11/Frameworks/Python.framework/Versions/3.11/lib/python3.11/inspect.py'>
      msg = 'mariadb-dump not found in PATH! This is required to take a backup.'
      out = {'message': 'mariadb-dump not found in PATH! This is required to take a backup.', 'title': 'Message', 'indicator': 'red', 'raise_exception': 1, '__frappe_exc_id': '7d64db905e167e15cf1424ca29f7b3b6d2942b1233df49028a935f72'}
      raise_exception = <class 'frappe.exceptions.ExecutableNotFound'>
frappe.exceptions.ExecutableNotFound: mariadb-dump not found in PATH! This is required to take a backup.
Backup failed for Site erpnexxt.local. Database or site_config.json may be corrupted
Traceback with variables (most recent call last):
  File "apps/frappe/frappe/commands/site.py", line 854, in backup
    odb = scheduled_backup(
      context = {'sites': ['erpnexxt.local'], 'force': False, 'verbose': True, 'profile': False}
      with_files = False
      backup_path = None
      backup_path_db = None
      backup_path_files = None
      backup_path_private_files = None
      backup_path_conf = None
      ignore_backup_conf = False
      verbose = True
      compress = False
      include = ''
      exclude = ''
      old_backup_metadata = False
      scheduled_backup = <function scheduled_backup at 0x107fdc0e0>
      exit_code = 0
      rollback_callback = None
      site = 'erpnexxt.local'
  File "apps/frappe/frappe/utils/backups.py", line 568, in scheduled_backup
    return new_backup(
      older_than = 6
      ignore_files = True
      backup_path = None
      backup_path_db = None
      backup_path_files = None
      backup_path_private_files = None
      backup_path_conf = None
      ignore_conf = False
      include_doctypes = ''
      exclude_doctypes = ''
      compress = False
      force = True
      verbose = True
      old_backup_metadata = False
      rollback_callback = <frappe.utils.CallbackManager object at 0x108220640>
  File "apps/frappe/frappe/utils/backups.py", line 626, in new_backup
    odb.get_backup(older_than, ignore_files, force=force)
      older_than = 6
      ignore_files = True
      backup_path = None
      backup_path_db = None
      backup_path_files = None
      backup_path_private_files = None
      backup_path_conf = None
      ignore_conf = False
      include_doctypes = ''
      exclude_doctypes = ''
      compress = False
      force = True
      verbose = True
      old_backup_metadata = False
      rollback_callback = <frappe.utils.CallbackManager object at 0x108220640>
      odb = <frappe.utils.backups.BackupGenerator object at 0x108201790>
  File "apps/frappe/frappe/utils/backups.py", line 195, in get_backup
    self.delete_if_step_fails(self.take_dump, self.backup_path_db)
      self = <frappe.utils.backups.BackupGenerator object at 0x108201790>
      older_than = 6
      ignore_files = True
      force = True
      last_db = False
      last_file = False
      last_private_file = False
      site_config_backup_path = False
  File "apps/frappe/frappe/utils/backups.py", line 520, in delete_if_step_fails
    raise e
      self = <frappe.utils.backups.BackupGenerator object at 0x108201790>
      step = <bound method BackupGenerator.take_dump of <frappe.utils.backups.BackupGenerator object at 0x108201790>>
      paths = ('./erpnexxt.local/private/backups/20250225_000004-erpnexxt_local-database.sql.gz',)
      path = './erpnexxt.local/private/backups/20250225_000004-erpnexxt_local-database.sql.gz'
  File "apps/frappe/frappe/utils/backups.py", line 515, in delete_if_step_fails
    step()
      self = <frappe.utils.backups.BackupGenerator object at 0x108201790>
      step = <bound method BackupGenerator.take_dump of <frappe.utils.backups.BackupGenerator object at 0x108201790>>
      paths = ('./erpnexxt.local/private/backups/20250225_000004-erpnexxt_local-database.sql.gz',)
      path = './erpnexxt.local/private/backups/20250225_000004-erpnexxt_local-database.sql.gz'
  File "apps/frappe/frappe/utils/backups.py", line 457, in take_dump
    frappe.throw(
      self = <frappe.utils.backups.BackupGenerator object at 0x108201790>
      shlex = <module 'shlex' from '/opt/homebrew/Cellar/python@3.11/3.11.11/Frameworks/Python.framework/Versions/3.11/lib/python3.11/shlex.py'>
      frappe = <module 'frappe' from 'apps/frappe/frappe/__init__.py'>
      get_app_branch = <function get_app_branch at 0x107fafd80>
      gzip_exc = '/usr/bin/gzip'
      database_header_content = ['begin frappe metadata', '[frappe]', 'version = 15.56.0', 'branch = master', 'end frappe metadata', '']
      generated_header = '-- begin frappe metadata\n-- [frappe]\n-- version = 15.56.0\n-- branch = master\n-- end frappe metadata\n-- \n'
      f = <_io.TextIOWrapper name='./erpnexxt.local/private/backups/20250225_000004-erpnexxt_local-database.sql.gz' encoding='UTF-8'>
      cmd = []
      extra = []
      get_command = <function get_command at 0x107f9e840>
      bin = None
      args = ['--user=_e7903427184a81b1', '--host=127.0.0.1', '--port=3306', '--password=eHVakHXsPB0Hhyx0', '--single-transaction', '--quick', '--lock-tables=false', '_e7903427184a81b1']
      bin_name = 'mariadb-dump'
  File "apps/frappe/frappe/__init__.py", line 603, in throw
    msgprint(
      msg = 'mariadb-dump not found in PATH! This is required to take a backup.'
      exc = <class 'frappe.exceptions.ExecutableNotFound'>
      title = None
      is_minimizable = False
      wide = False
      as_list = False
      primary_action = None
  File "apps/frappe/frappe/__init__.py", line 568, in msgprint
    _raise_exception()
      msg = 'mariadb-dump not found in PATH! This is required to take a backup.'
      title = None
      raise_exception = <class 'frappe.exceptions.ExecutableNotFound'>
      as_table = False
      as_list = False
      indicator = 'red'
      alert = False
      primary_action = None
      is_minimizable = False
      wide = False
      realtime = False
      sys = <module 'sys' (built-in)>
      _raise_exception = <function msgprint.<locals>._raise_exception at 0x1083df920>
      inspect = <module 'inspect' from '/opt/homebrew/Cellar/python@3.11/3.11.11/Frameworks/Python.framework/Versions/3.11/lib/python3.11/inspect.py'>
      out = {'message': 'mariadb-dump not found in PATH! This is required to take a backup.', 'title': 'Message', 'indicator': 'red', 'raise_exception': 1, '__frappe_exc_id': '9afb38ee57aa7283f997f6ddc55860c2aab76a87fbc7c74be6c18498'}
  File "apps/frappe/frappe/__init__.py", line 519, in _raise_exception
    raise exc
      exc = ExecutableNotFound('mariadb-dump not found in PATH! This is required to take a backup.')
      inspect = <module 'inspect' from '/opt/homebrew/Cellar/python@3.11/3.11.11/Frameworks/Python.framework/Versions/3.11/lib/python3.11/inspect.py'>
      msg = 'mariadb-dump not found in PATH! This is required to take a backup.'
      out = {'message': 'mariadb-dump not found in PATH! This is required to take a backup.', 'title': 'Message', 'indicator': 'red', 'raise_exception': 1, '__frappe_exc_id': '9afb38ee57aa7283f997f6ddc55860c2aab76a87fbc7c74be6c18498'}
      raise_exception = <class 'frappe.exceptions.ExecutableNotFound'>
frappe.exceptions.ExecutableNotFound: mariadb-dump not found in PATH! This is required to take a backup.
Backup failed for Site erpnexxt.local. Database or site_config.json may be corrupted
Traceback with variables (most recent call last):
  File "apps/frappe/frappe/commands/site.py", line 854, in backup
    odb = scheduled_backup(
      context = {'sites': ['erpnexxt.local'], 'force': False, 'verbose': True, 'profile': False}
      with_files = False
      backup_path = None
      backup_path_db = None
      backup_path_files = None
      backup_path_private_files = None
      backup_path_conf = None
      ignore_backup_conf = False
      verbose = True
      compress = False
      include = ''
      exclude = ''
      old_backup_metadata = False
      scheduled_backup = <function scheduled_backup at 0x1037740e0>
      exit_code = 0
      rollback_callback = None
      site = 'erpnexxt.local'
  File "apps/frappe/frappe/utils/backups.py", line 568, in scheduled_backup
    return new_backup(
      older_than = 6
      ignore_files = True
      backup_path = None
      backup_path_db = None
      backup_path_files = None
      backup_path_private_files = None
      backup_path_conf = None
      ignore_conf = False
      include_doctypes = ''
      exclude_doctypes = ''
      compress = False
      force = True
      verbose = True
      old_backup_metadata = False
      rollback_callback = <frappe.utils.CallbackManager object at 0x1039b8640>
  File "apps/frappe/frappe/utils/backups.py", line 626, in new_backup
    odb.get_backup(older_than, ignore_files, force=force)
      older_than = 6
      ignore_files = True
      backup_path = None
      backup_path_db = None
      backup_path_files = None
      backup_path_private_files = None
      backup_path_conf = None
      ignore_conf = False
      include_doctypes = ''
      exclude_doctypes = ''
      compress = False
      force = True
      verbose = True
      old_backup_metadata = False
      rollback_callback = <frappe.utils.CallbackManager object at 0x1039b8640>
      odb = <frappe.utils.backups.BackupGenerator object at 0x103999d50>
  File "apps/frappe/frappe/utils/backups.py", line 195, in get_backup
    self.delete_if_step_fails(self.take_dump, self.backup_path_db)
      self = <frappe.utils.backups.BackupGenerator object at 0x103999d50>
      older_than = 6
      ignore_files = True
      force = True
      last_db = False
      last_file = False
      last_private_file = False
      site_config_backup_path = False
  File "apps/frappe/frappe/utils/backups.py", line 520, in delete_if_step_fails
    raise e
      self = <frappe.utils.backups.BackupGenerator object at 0x103999d50>
      step = <bound method BackupGenerator.take_dump of <frappe.utils.backups.BackupGenerator object at 0x103999d50>>
      paths = ('./erpnexxt.local/private/backups/20250225_060009-erpnexxt_local-database.sql.gz',)
      path = './erpnexxt.local/private/backups/20250225_060009-erpnexxt_local-database.sql.gz'
  File "apps/frappe/frappe/utils/backups.py", line 515, in delete_if_step_fails
    step()
      self = <frappe.utils.backups.BackupGenerator object at 0x103999d50>
      step = <bound method BackupGenerator.take_dump of <frappe.utils.backups.BackupGenerator object at 0x103999d50>>
      paths = ('./erpnexxt.local/private/backups/20250225_060009-erpnexxt_local-database.sql.gz',)
      path = './erpnexxt.local/private/backups/20250225_060009-erpnexxt_local-database.sql.gz'
  File "apps/frappe/frappe/utils/backups.py", line 457, in take_dump
    frappe.throw(
      self = <frappe.utils.backups.BackupGenerator object at 0x103999d50>
      shlex = <module 'shlex' from '/opt/homebrew/Cellar/python@3.11/3.11.11/Frameworks/Python.framework/Versions/3.11/lib/python3.11/shlex.py'>
      frappe = <module 'frappe' from 'apps/frappe/frappe/__init__.py'>
      get_app_branch = <function get_app_branch at 0x103747d80>
      gzip_exc = '/usr/bin/gzip'
      database_header_content = ['begin frappe metadata', '[frappe]', 'version = 15.56.0', 'branch = master', 'end frappe metadata', '']
      generated_header = '-- begin frappe metadata\n-- [frappe]\n-- version = 15.56.0\n-- branch = master\n-- end frappe metadata\n-- \n'
      f = <_io.TextIOWrapper name='./erpnexxt.local/private/backups/20250225_060009-erpnexxt_local-database.sql.gz' encoding='UTF-8'>
      cmd = []
      extra = []
      get_command = <function get_command at 0x103736840>
      bin = None
      args = ['--user=_e7903427184a81b1', '--host=127.0.0.1', '--port=3306', '--password=eHVakHXsPB0Hhyx0', '--single-transaction', '--quick', '--lock-tables=false', '_e7903427184a81b1']
      bin_name = 'mariadb-dump'
  File "apps/frappe/frappe/__init__.py", line 603, in throw
    msgprint(
      msg = 'mariadb-dump not found in PATH! This is required to take a backup.'
      exc = <class 'frappe.exceptions.ExecutableNotFound'>
      title = None
      is_minimizable = False
      wide = False
      as_list = False
      primary_action = None
  File "apps/frappe/frappe/__init__.py", line 568, in msgprint
    _raise_exception()
      msg = 'mariadb-dump not found in PATH! This is required to take a backup.'
      title = None
      raise_exception = <class 'frappe.exceptions.ExecutableNotFound'>
      as_table = False
      as_list = False
      indicator = 'red'
      alert = False
      primary_action = None
      is_minimizable = False
      wide = False
      realtime = False
      sys = <module 'sys' (built-in)>
      _raise_exception = <function msgprint.<locals>._raise_exception at 0x103c77920>
      inspect = <module 'inspect' from '/opt/homebrew/Cellar/python@3.11/3.11.11/Frameworks/Python.framework/Versions/3.11/lib/python3.11/inspect.py'>
      out = {'message': 'mariadb-dump not found in PATH! This is required to take a backup.', 'title': 'Message', 'indicator': 'red', 'raise_exception': 1, '__frappe_exc_id': '7b1905373f688b7eb7531159353f7797b6e1d080c4b19e830f296c28'}
  File "apps/frappe/frappe/__init__.py", line 519, in _raise_exception
    raise exc
      exc = ExecutableNotFound('mariadb-dump not found in PATH! This is required to take a backup.')
      inspect = <module 'inspect' from '/opt/homebrew/Cellar/python@3.11/3.11.11/Frameworks/Python.framework/Versions/3.11/lib/python3.11/inspect.py'>
      msg = 'mariadb-dump not found in PATH! This is required to take a backup.'
      out = {'message': 'mariadb-dump not found in PATH! This is required to take a backup.', 'title': 'Message', 'indicator': 'red', 'raise_exception': 1, '__frappe_exc_id': '7b1905373f688b7eb7531159353f7797b6e1d080c4b19e830f296c28'}
      raise_exception = <class 'frappe.exceptions.ExecutableNotFound'>
frappe.exceptions.ExecutableNotFound: mariadb-dump not found in PATH! This is required to take a backup.
Backup failed for Site erpnexxt.local. Database or site_config.json may be corrupted
Traceback with variables (most recent call last):
  File "apps/frappe/frappe/commands/site.py", line 854, in backup
    odb = scheduled_backup(
      context = {'sites': ['erpnexxt.local'], 'force': False, 'verbose': True, 'profile': False}
      with_files = False
      backup_path = None
      backup_path_db = None
      backup_path_files = None
      backup_path_private_files = None
      backup_path_conf = None
      ignore_backup_conf = False
      verbose = True
      compress = False
      include = ''
      exclude = ''
      old_backup_metadata = False
      scheduled_backup = <function scheduled_backup at 0x107fdc0e0>
      exit_code = 0
      rollback_callback = None
      site = 'erpnexxt.local'
  File "apps/frappe/frappe/utils/backups.py", line 568, in scheduled_backup
    return new_backup(
      older_than = 6
      ignore_files = True
      backup_path = None
      backup_path_db = None
      backup_path_files = None
      backup_path_private_files = None
      backup_path_conf = None
      ignore_conf = False
      include_doctypes = ''
      exclude_doctypes = ''
      compress = False
      force = True
      verbose = True
      old_backup_metadata = False
      rollback_callback = <frappe.utils.CallbackManager object at 0x108220640>
  File "apps/frappe/frappe/utils/backups.py", line 626, in new_backup
    odb.get_backup(older_than, ignore_files, force=force)
      older_than = 6
      ignore_files = True
      backup_path = None
      backup_path_db = None
      backup_path_files = None
      backup_path_private_files = None
      backup_path_conf = None
      ignore_conf = False
      include_doctypes = ''
      exclude_doctypes = ''
      compress = False
      force = True
      verbose = True
      old_backup_metadata = False
      rollback_callback = <frappe.utils.CallbackManager object at 0x108220640>
      odb = <frappe.utils.backups.BackupGenerator object at 0x108201d10>
  File "apps/frappe/frappe/utils/backups.py", line 195, in get_backup
    self.delete_if_step_fails(self.take_dump, self.backup_path_db)
      self = <frappe.utils.backups.BackupGenerator object at 0x108201d10>
      older_than = 6
      ignore_files = True
      force = True
      last_db = False
      last_file = False
      last_private_file = False
      site_config_backup_path = False
  File "apps/frappe/frappe/utils/backups.py", line 520, in delete_if_step_fails
    raise e
      self = <frappe.utils.backups.BackupGenerator object at 0x108201d10>
      step = <bound method BackupGenerator.take_dump of <frappe.utils.backups.BackupGenerator object at 0x108201d10>>
      paths = ('./erpnexxt.local/private/backups/20250225_180208-erpnexxt_local-database.sql.gz',)
      path = './erpnexxt.local/private/backups/20250225_180208-erpnexxt_local-database.sql.gz'
  File "apps/frappe/frappe/utils/backups.py", line 515, in delete_if_step_fails
    step()
      self = <frappe.utils.backups.BackupGenerator object at 0x108201d10>
      step = <bound method BackupGenerator.take_dump of <frappe.utils.backups.BackupGenerator object at 0x108201d10>>
      paths = ('./erpnexxt.local/private/backups/20250225_180208-erpnexxt_local-database.sql.gz',)
      path = './erpnexxt.local/private/backups/20250225_180208-erpnexxt_local-database.sql.gz'
  File "apps/frappe/frappe/utils/backups.py", line 457, in take_dump
    frappe.throw(
      self = <frappe.utils.backups.BackupGenerator object at 0x108201d10>
      shlex = <module 'shlex' from '/opt/homebrew/Cellar/python@3.11/3.11.11/Frameworks/Python.framework/Versions/3.11/lib/python3.11/shlex.py'>
      frappe = <module 'frappe' from 'apps/frappe/frappe/__init__.py'>
      get_app_branch = <function get_app_branch at 0x107fafd80>
      gzip_exc = '/usr/bin/gzip'
      database_header_content = ['begin frappe metadata', '[frappe]', 'version = 15.56.0', 'branch = master', 'end frappe metadata', '']
      generated_header = '-- begin frappe metadata\n-- [frappe]\n-- version = 15.56.0\n-- branch = master\n-- end frappe metadata\n-- \n'
      f = <_io.TextIOWrapper name='./erpnexxt.local/private/backups/20250225_180208-erpnexxt_local-database.sql.gz' encoding='UTF-8'>
      cmd = []
      extra = []
      get_command = <function get_command at 0x107f9e840>
      bin = None
      args = ['--user=_e7903427184a81b1', '--host=127.0.0.1', '--port=3306', '--password=eHVakHXsPB0Hhyx0', '--single-transaction', '--quick', '--lock-tables=false', '_e7903427184a81b1']
      bin_name = 'mariadb-dump'
  File "apps/frappe/frappe/__init__.py", line 603, in throw
    msgprint(
      msg = 'mariadb-dump not found in PATH! This is required to take a backup.'
      exc = <class 'frappe.exceptions.ExecutableNotFound'>
      title = None
      is_minimizable = False
      wide = False
      as_list = False
      primary_action = None
  File "apps/frappe/frappe/__init__.py", line 568, in msgprint
    _raise_exception()
      msg = 'mariadb-dump not found in PATH! This is required to take a backup.'
      title = None
      raise_exception = <class 'frappe.exceptions.ExecutableNotFound'>
      as_table = False
      as_list = False
      indicator = 'red'
      alert = False
      primary_action = None
      is_minimizable = False
      wide = False
      realtime = False
      sys = <module 'sys' (built-in)>
      _raise_exception = <function msgprint.<locals>._raise_exception at 0x1083df920>
      inspect = <module 'inspect' from '/opt/homebrew/Cellar/python@3.11/3.11.11/Frameworks/Python.framework/Versions/3.11/lib/python3.11/inspect.py'>
      out = {'message': 'mariadb-dump not found in PATH! This is required to take a backup.', 'title': 'Message', 'indicator': 'red', 'raise_exception': 1, '__frappe_exc_id': '1d40a1c2a0ef64f5281c6b1360924f5b8f8aa224c045b92e83706018'}
  File "apps/frappe/frappe/__init__.py", line 519, in _raise_exception
    raise exc
      exc = ExecutableNotFound('mariadb-dump not found in PATH! This is required to take a backup.')
      inspect = <module 'inspect' from '/opt/homebrew/Cellar/python@3.11/3.11.11/Frameworks/Python.framework/Versions/3.11/lib/python3.11/inspect.py'>
      msg = 'mariadb-dump not found in PATH! This is required to take a backup.'
      out = {'message': 'mariadb-dump not found in PATH! This is required to take a backup.', 'title': 'Message', 'indicator': 'red', 'raise_exception': 1, '__frappe_exc_id': '1d40a1c2a0ef64f5281c6b1360924f5b8f8aa224c045b92e83706018'}
      raise_exception = <class 'frappe.exceptions.ExecutableNotFound'>
frappe.exceptions.ExecutableNotFound: mariadb-dump not found in PATH! This is required to take a backup.
Backup failed for Site erpnexxt.local. Database or site_config.json may be corrupted
Traceback with variables (most recent call last):
  File "apps/frappe/frappe/commands/site.py", line 854, in backup
    odb = scheduled_backup(
      context = {'sites': ['erpnexxt.local'], 'force': False, 'verbose': True, 'profile': False}
      with_files = False
      backup_path = None
      backup_path_db = None
      backup_path_files = None
      backup_path_private_files = None
      backup_path_conf = None
      ignore_backup_conf = False
      verbose = True
      compress = False
      include = ''
      exclude = ''
      old_backup_metadata = False
      scheduled_backup = <function scheduled_backup at 0x1079a40e0>
      exit_code = 0
      rollback_callback = None
      site = 'erpnexxt.local'
  File "apps/frappe/frappe/utils/backups.py", line 568, in scheduled_backup
    return new_backup(
      older_than = 6
      ignore_files = True
      backup_path = None
      backup_path_db = None
      backup_path_files = None
      backup_path_private_files = None
      backup_path_conf = None
      ignore_conf = False
      include_doctypes = ''
      exclude_doctypes = ''
      compress = False
      force = True
      verbose = True
      old_backup_metadata = False
      rollback_callback = <frappe.utils.CallbackManager object at 0x107be8640>
  File "apps/frappe/frappe/utils/backups.py", line 626, in new_backup
    odb.get_backup(older_than, ignore_files, force=force)
      older_than = 6
      ignore_files = True
      backup_path = None
      backup_path_db = None
      backup_path_files = None
      backup_path_private_files = None
      backup_path_conf = None
      ignore_conf = False
      include_doctypes = ''
      exclude_doctypes = ''
      compress = False
      force = True
      verbose = True
      old_backup_metadata = False
      rollback_callback = <frappe.utils.CallbackManager object at 0x107be8640>
      odb = <frappe.utils.backups.BackupGenerator object at 0x107bc9410>
  File "apps/frappe/frappe/utils/backups.py", line 195, in get_backup
    self.delete_if_step_fails(self.take_dump, self.backup_path_db)
      self = <frappe.utils.backups.BackupGenerator object at 0x107bc9410>
      older_than = 6
      ignore_files = True
      force = True
      last_db = False
      last_file = False
      last_private_file = False
      site_config_backup_path = False
  File "apps/frappe/frappe/utils/backups.py", line 520, in delete_if_step_fails
    raise e
      self = <frappe.utils.backups.BackupGenerator object at 0x107bc9410>
      step = <bound method BackupGenerator.take_dump of <frappe.utils.backups.BackupGenerator object at 0x107bc9410>>
      paths = ('./erpnexxt.local/private/backups/20250226_180003-erpnexxt_local-database.sql.gz',)
      path = './erpnexxt.local/private/backups/20250226_180003-erpnexxt_local-database.sql.gz'
  File "apps/frappe/frappe/utils/backups.py", line 515, in delete_if_step_fails
    step()
      self = <frappe.utils.backups.BackupGenerator object at 0x107bc9410>
      step = <bound method BackupGenerator.take_dump of <frappe.utils.backups.BackupGenerator object at 0x107bc9410>>
      paths = ('./erpnexxt.local/private/backups/20250226_180003-erpnexxt_local-database.sql.gz',)
      path = './erpnexxt.local/private/backups/20250226_180003-erpnexxt_local-database.sql.gz'
  File "apps/frappe/frappe/utils/backups.py", line 457, in take_dump
    frappe.throw(
      self = <frappe.utils.backups.BackupGenerator object at 0x107bc9410>
      shlex = <module 'shlex' from '/opt/homebrew/Cellar/python@3.11/3.11.11/Frameworks/Python.framework/Versions/3.11/lib/python3.11/shlex.py'>
      frappe = <module 'frappe' from 'apps/frappe/frappe/__init__.py'>
      get_app_branch = <function get_app_branch at 0x107977d80>
      gzip_exc = '/usr/bin/gzip'
      database_header_content = ['begin frappe metadata', '[frappe]', 'version = 15.56.0', 'branch = master', 'end frappe metadata', '']
      generated_header = '-- begin frappe metadata\n-- [frappe]\n-- version = 15.56.0\n-- branch = master\n-- end frappe metadata\n-- \n'
      f = <_io.TextIOWrapper name='./erpnexxt.local/private/backups/20250226_180003-erpnexxt_local-database.sql.gz' encoding='UTF-8'>
      cmd = []
      extra = []
      get_command = <function get_command at 0x107966840>
      bin = None
      args = ['--user=_e7903427184a81b1', '--host=127.0.0.1', '--port=3306', '--password=eHVakHXsPB0Hhyx0', '--single-transaction', '--quick', '--lock-tables=false', '_e7903427184a81b1']
      bin_name = 'mariadb-dump'
  File "apps/frappe/frappe/__init__.py", line 603, in throw
    msgprint(
      msg = 'mariadb-dump not found in PATH! This is required to take a backup.'
      exc = <class 'frappe.exceptions.ExecutableNotFound'>
      title = None
      is_minimizable = False
      wide = False
      as_list = False
      primary_action = None
  File "apps/frappe/frappe/__init__.py", line 568, in msgprint
    _raise_exception()
      msg = 'mariadb-dump not found in PATH! This is required to take a backup.'
      title = None
      raise_exception = <class 'frappe.exceptions.ExecutableNotFound'>
      as_table = False
      as_list = False
      indicator = 'red'
      alert = False
      primary_action = None
      is_minimizable = False
      wide = False
      realtime = False
      sys = <module 'sys' (built-in)>
      _raise_exception = <function msgprint.<locals>._raise_exception at 0x107da7920>
      inspect = <module 'inspect' from '/opt/homebrew/Cellar/python@3.11/3.11.11/Frameworks/Python.framework/Versions/3.11/lib/python3.11/inspect.py'>
      out = {'message': 'mariadb-dump not found in PATH! This is required to take a backup.', 'title': 'Message', 'indicator': 'red', 'raise_exception': 1, '__frappe_exc_id': '3d829553584e23ece0dae6db86d386ddd291c8f6e8b0d8c84421f287'}
  File "apps/frappe/frappe/__init__.py", line 519, in _raise_exception
    raise exc
      exc = ExecutableNotFound('mariadb-dump not found in PATH! This is required to take a backup.')
      inspect = <module 'inspect' from '/opt/homebrew/Cellar/python@3.11/3.11.11/Frameworks/Python.framework/Versions/3.11/lib/python3.11/inspect.py'>
      msg = 'mariadb-dump not found in PATH! This is required to take a backup.'
      out = {'message': 'mariadb-dump not found in PATH! This is required to take a backup.', 'title': 'Message', 'indicator': 'red', 'raise_exception': 1, '__frappe_exc_id': '3d829553584e23ece0dae6db86d386ddd291c8f6e8b0d8c84421f287'}
      raise_exception = <class 'frappe.exceptions.ExecutableNotFound'>
frappe.exceptions.ExecutableNotFound: mariadb-dump not found in PATH! This is required to take a backup.
Backup failed for Site erpnexxt.local. Database or site_config.json may be corrupted
Traceback with variables (most recent call last):
  File "apps/frappe/frappe/commands/site.py", line 854, in backup
    odb = scheduled_backup(
      context = {'sites': ['erpnexxt.local'], 'force': False, 'verbose': True, 'profile': False}
      with_files = False
      backup_path = None
      backup_path_db = None
      backup_path_files = None
      backup_path_private_files = None
      backup_path_conf = None
      ignore_backup_conf = False
      verbose = True
      compress = False
      include = ''
      exclude = ''
      old_backup_metadata = False
      scheduled_backup = <function scheduled_backup at 0x1061740e0>
      exit_code = 0
      rollback_callback = None
      site = 'erpnexxt.local'
  File "apps/frappe/frappe/utils/backups.py", line 568, in scheduled_backup
    return new_backup(
      older_than = 6
      ignore_files = True
      backup_path = None
      backup_path_db = None
      backup_path_files = None
      backup_path_private_files = None
      backup_path_conf = None
      ignore_conf = False
      include_doctypes = ''
      exclude_doctypes = ''
      compress = False
      force = True
      verbose = True
      old_backup_metadata = False
      rollback_callback = <frappe.utils.CallbackManager object at 0x1063b8640>
  File "apps/frappe/frappe/utils/backups.py", line 626, in new_backup
    odb.get_backup(older_than, ignore_files, force=force)
      older_than = 6
      ignore_files = True
      backup_path = None
      backup_path_db = None
      backup_path_files = None
      backup_path_private_files = None
      backup_path_conf = None
      ignore_conf = False
      include_doctypes = ''
      exclude_doctypes = ''
      compress = False
      force = True
      verbose = True
      old_backup_metadata = False
      rollback_callback = <frappe.utils.CallbackManager object at 0x1063b8640>
      odb = <frappe.utils.backups.BackupGenerator object at 0x106399c10>
  File "apps/frappe/frappe/utils/backups.py", line 195, in get_backup
    self.delete_if_step_fails(self.take_dump, self.backup_path_db)
      self = <frappe.utils.backups.BackupGenerator object at 0x106399c10>
      older_than = 6
      ignore_files = True
      force = True
      last_db = False
      last_file = False
      last_private_file = False
      site_config_backup_path = False
  File "apps/frappe/frappe/utils/backups.py", line 520, in delete_if_step_fails
    raise e
      self = <frappe.utils.backups.BackupGenerator object at 0x106399c10>
      step = <bound method BackupGenerator.take_dump of <frappe.utils.backups.BackupGenerator object at 0x106399c10>>
      paths = ('./erpnexxt.local/private/backups/20250227_000330-erpnexxt_local-database.sql.gz',)
      path = './erpnexxt.local/private/backups/20250227_000330-erpnexxt_local-database.sql.gz'
  File "apps/frappe/frappe/utils/backups.py", line 515, in delete_if_step_fails
    step()
      self = <frappe.utils.backups.BackupGenerator object at 0x106399c10>
      step = <bound method BackupGenerator.take_dump of <frappe.utils.backups.BackupGenerator object at 0x106399c10>>
      paths = ('./erpnexxt.local/private/backups/20250227_000330-erpnexxt_local-database.sql.gz',)
      path = './erpnexxt.local/private/backups/20250227_000330-erpnexxt_local-database.sql.gz'
  File "apps/frappe/frappe/utils/backups.py", line 457, in take_dump
    frappe.throw(
      self = <frappe.utils.backups.BackupGenerator object at 0x106399c10>
      shlex = <module 'shlex' from '/opt/homebrew/Cellar/python@3.11/3.11.11/Frameworks/Python.framework/Versions/3.11/lib/python3.11/shlex.py'>
      frappe = <module 'frappe' from 'apps/frappe/frappe/__init__.py'>
      get_app_branch = <function get_app_branch at 0x106147d80>
      gzip_exc = '/usr/bin/gzip'
      database_header_content = ['begin frappe metadata', '[frappe]', 'version = 15.56.0', 'branch = master', 'end frappe metadata', '']
      generated_header = '-- begin frappe metadata\n-- [frappe]\n-- version = 15.56.0\n-- branch = master\n-- end frappe metadata\n-- \n'
      f = <_io.TextIOWrapper name='./erpnexxt.local/private/backups/20250227_000330-erpnexxt_local-database.sql.gz' encoding='UTF-8'>
      cmd = []
      extra = []
      get_command = <function get_command at 0x106136840>
      bin = None
      args = ['--user=_e7903427184a81b1', '--host=127.0.0.1', '--port=3306', '--password=eHVakHXsPB0Hhyx0', '--single-transaction', '--quick', '--lock-tables=false', '_e7903427184a81b1']
      bin_name = 'mariadb-dump'
  File "apps/frappe/frappe/__init__.py", line 603, in throw
    msgprint(
      msg = 'mariadb-dump not found in PATH! This is required to take a backup.'
      exc = <class 'frappe.exceptions.ExecutableNotFound'>
      title = None
      is_minimizable = False
      wide = False
      as_list = False
      primary_action = None
  File "apps/frappe/frappe/__init__.py", line 568, in msgprint
    _raise_exception()
      msg = 'mariadb-dump not found in PATH! This is required to take a backup.'
      title = None
      raise_exception = <class 'frappe.exceptions.ExecutableNotFound'>
      as_table = False
      as_list = False
      indicator = 'red'
      alert = False
      primary_action = None
      is_minimizable = False
      wide = False
      realtime = False
      sys = <module 'sys' (built-in)>
      _raise_exception = <function msgprint.<locals>._raise_exception at 0x106577920>
      inspect = <module 'inspect' from '/opt/homebrew/Cellar/python@3.11/3.11.11/Frameworks/Python.framework/Versions/3.11/lib/python3.11/inspect.py'>
      out = {'message': 'mariadb-dump not found in PATH! This is required to take a backup.', 'title': 'Message', 'indicator': 'red', 'raise_exception': 1, '__frappe_exc_id': '364b321b468a6164a0cd129a7f1141b5c19a3cab9a5b3f15b57bf03a'}
  File "apps/frappe/frappe/__init__.py", line 519, in _raise_exception
    raise exc
      exc = ExecutableNotFound('mariadb-dump not found in PATH! This is required to take a backup.')
      inspect = <module 'inspect' from '/opt/homebrew/Cellar/python@3.11/3.11.11/Frameworks/Python.framework/Versions/3.11/lib/python3.11/inspect.py'>
      msg = 'mariadb-dump not found in PATH! This is required to take a backup.'
      out = {'message': 'mariadb-dump not found in PATH! This is required to take a backup.', 'title': 'Message', 'indicator': 'red', 'raise_exception': 1, '__frappe_exc_id': '364b321b468a6164a0cd129a7f1141b5c19a3cab9a5b3f15b57bf03a'}
      raise_exception = <class 'frappe.exceptions.ExecutableNotFound'>
frappe.exceptions.ExecutableNotFound: mariadb-dump not found in PATH! This is required to take a backup.
Backup failed for Site erpnexxt.local. Database or site_config.json may be corrupted
Traceback with variables (most recent call last):
  File "apps/frappe/frappe/commands/site.py", line 854, in backup
    odb = scheduled_backup(
      context = {'sites': ['erpnexxt.local'], 'force': False, 'verbose': True, 'profile': False}
      with_files = False
      backup_path = None
      backup_path_db = None
      backup_path_files = None
      backup_path_private_files = None
      backup_path_conf = None
      ignore_backup_conf = False
      verbose = True
      compress = False
      include = ''
      exclude = ''
      old_backup_metadata = False
      scheduled_backup = <function scheduled_backup at 0x105cf40e0>
      exit_code = 0
      rollback_callback = None
      site = 'erpnexxt.local'
  File "apps/frappe/frappe/utils/backups.py", line 568, in scheduled_backup
    return new_backup(
      older_than = 6
      ignore_files = True
      backup_path = None
      backup_path_db = None
      backup_path_files = None
      backup_path_private_files = None
      backup_path_conf = None
      ignore_conf = False
      include_doctypes = ''
      exclude_doctypes = ''
      compress = False
      force = True
      verbose = True
      old_backup_metadata = False
      rollback_callback = <frappe.utils.CallbackManager object at 0x105f38640>
  File "apps/frappe/frappe/utils/backups.py", line 626, in new_backup
    odb.get_backup(older_than, ignore_files, force=force)
      older_than = 6
      ignore_files = True
      backup_path = None
      backup_path_db = None
      backup_path_files = None
      backup_path_private_files = None
      backup_path_conf = None
      ignore_conf = False
      include_doctypes = ''
      exclude_doctypes = ''
      compress = False
      force = True
      verbose = True
      old_backup_metadata = False
      rollback_callback = <frappe.utils.CallbackManager object at 0x105f38640>
      odb = <frappe.utils.backups.BackupGenerator object at 0x105f19d10>
  File "apps/frappe/frappe/utils/backups.py", line 195, in get_backup
    self.delete_if_step_fails(self.take_dump, self.backup_path_db)
      self = <frappe.utils.backups.BackupGenerator object at 0x105f19d10>
      older_than = 6
      ignore_files = True
      force = True
      last_db = False
      last_file = False
      last_private_file = False
      site_config_backup_path = False
  File "apps/frappe/frappe/utils/backups.py", line 520, in delete_if_step_fails
    raise e
      self = <frappe.utils.backups.BackupGenerator object at 0x105f19d10>
      step = <bound method BackupGenerator.take_dump of <frappe.utils.backups.BackupGenerator object at 0x105f19d10>>
      paths = ('./erpnexxt.local/private/backups/20250227_060001-erpnexxt_local-database.sql.gz',)
      path = './erpnexxt.local/private/backups/20250227_060001-erpnexxt_local-database.sql.gz'
  File "apps/frappe/frappe/utils/backups.py", line 515, in delete_if_step_fails
    step()
      self = <frappe.utils.backups.BackupGenerator object at 0x105f19d10>
      step = <bound method BackupGenerator.take_dump of <frappe.utils.backups.BackupGenerator object at 0x105f19d10>>
      paths = ('./erpnexxt.local/private/backups/20250227_060001-erpnexxt_local-database.sql.gz',)
      path = './erpnexxt.local/private/backups/20250227_060001-erpnexxt_local-database.sql.gz'
  File "apps/frappe/frappe/utils/backups.py", line 457, in take_dump
    frappe.throw(
      self = <frappe.utils.backups.BackupGenerator object at 0x105f19d10>
      shlex = <module 'shlex' from '/opt/homebrew/Cellar/python@3.11/3.11.11/Frameworks/Python.framework/Versions/3.11/lib/python3.11/shlex.py'>
      frappe = <module 'frappe' from 'apps/frappe/frappe/__init__.py'>
      get_app_branch = <function get_app_branch at 0x105cc7d80>
      gzip_exc = '/usr/bin/gzip'
      database_header_content = ['begin frappe metadata', '[frappe]', 'version = 15.56.0', 'branch = master', 'end frappe metadata', '']
      generated_header = '-- begin frappe metadata\n-- [frappe]\n-- version = 15.56.0\n-- branch = master\n-- end frappe metadata\n-- \n'
      f = <_io.TextIOWrapper name='./erpnexxt.local/private/backups/20250227_060001-erpnexxt_local-database.sql.gz' encoding='UTF-8'>
      cmd = []
      extra = []
      get_command = <function get_command at 0x105cb6840>
      bin = None
      args = ['--user=_e7903427184a81b1', '--host=127.0.0.1', '--port=3306', '--password=eHVakHXsPB0Hhyx0', '--single-transaction', '--quick', '--lock-tables=false', '_e7903427184a81b1']
      bin_name = 'mariadb-dump'
  File "apps/frappe/frappe/__init__.py", line 603, in throw
    msgprint(
      msg = 'mariadb-dump not found in PATH! This is required to take a backup.'
      exc = <class 'frappe.exceptions.ExecutableNotFound'>
      title = None
      is_minimizable = False
      wide = False
      as_list = False
      primary_action = None
  File "apps/frappe/frappe/__init__.py", line 568, in msgprint
    _raise_exception()
      msg = 'mariadb-dump not found in PATH! This is required to take a backup.'
      title = None
      raise_exception = <class 'frappe.exceptions.ExecutableNotFound'>
      as_table = False
      as_list = False
      indicator = 'red'
      alert = False
      primary_action = None
      is_minimizable = False
      wide = False
      realtime = False
      sys = <module 'sys' (built-in)>
      _raise_exception = <function msgprint.<locals>._raise_exception at 0x1060f7920>
      inspect = <module 'inspect' from '/opt/homebrew/Cellar/python@3.11/3.11.11/Frameworks/Python.framework/Versions/3.11/lib/python3.11/inspect.py'>
      out = {'message': 'mariadb-dump not found in PATH! This is required to take a backup.', 'title': 'Message', 'indicator': 'red', 'raise_exception': 1, '__frappe_exc_id': '33049271a5c8f8808b384907b5710556e1147bd66d2f8ef88c8d2d5c'}
  File "apps/frappe/frappe/__init__.py", line 519, in _raise_exception
    raise exc
      exc = ExecutableNotFound('mariadb-dump not found in PATH! This is required to take a backup.')
      inspect = <module 'inspect' from '/opt/homebrew/Cellar/python@3.11/3.11.11/Frameworks/Python.framework/Versions/3.11/lib/python3.11/inspect.py'>
      msg = 'mariadb-dump not found in PATH! This is required to take a backup.'
      out = {'message': 'mariadb-dump not found in PATH! This is required to take a backup.', 'title': 'Message', 'indicator': 'red', 'raise_exception': 1, '__frappe_exc_id': '33049271a5c8f8808b384907b5710556e1147bd66d2f8ef88c8d2d5c'}
      raise_exception = <class 'frappe.exceptions.ExecutableNotFound'>
frappe.exceptions.ExecutableNotFound: mariadb-dump not found in PATH! This is required to take a backup.
Backup failed for Site erpnexxt.local. Database or site_config.json may be corrupted
Traceback with variables (most recent call last):
  File "apps/frappe/frappe/commands/site.py", line 854, in backup
    odb = scheduled_backup(
      context = {'sites': ['erpnexxt.local'], 'force': False, 'verbose': True, 'profile': False}
      with_files = False
      backup_path = None
      backup_path_db = None
      backup_path_files = None
      backup_path_private_files = None
      backup_path_conf = None
      ignore_backup_conf = False
      verbose = True
      compress = False
      include = ''
      exclude = ''
      old_backup_metadata = False
      scheduled_backup = <function scheduled_backup at 0x1054100e0>
      exit_code = 0
      rollback_callback = None
      site = 'erpnexxt.local'
  File "apps/frappe/frappe/utils/backups.py", line 568, in scheduled_backup
    return new_backup(
      older_than = 6
      ignore_files = True
      backup_path = None
      backup_path_db = None
      backup_path_files = None
      backup_path_private_files = None
      backup_path_conf = None
      ignore_conf = False
      include_doctypes = ''
      exclude_doctypes = ''
      compress = False
      force = True
      verbose = True
      old_backup_metadata = False
      rollback_callback = <frappe.utils.CallbackManager object at 0x105658340>
  File "apps/frappe/frappe/utils/backups.py", line 626, in new_backup
    odb.get_backup(older_than, ignore_files, force=force)
      older_than = 6
      ignore_files = True
      backup_path = None
      backup_path_db = None
      backup_path_files = None
      backup_path_private_files = None
      backup_path_conf = None
      ignore_conf = False
      include_doctypes = ''
      exclude_doctypes = ''
      compress = False
      force = True
      verbose = True
      old_backup_metadata = False
      rollback_callback = <frappe.utils.CallbackManager object at 0x105658340>
      odb = <frappe.utils.backups.BackupGenerator object at 0x10547f710>
  File "apps/frappe/frappe/utils/backups.py", line 195, in get_backup
    self.delete_if_step_fails(self.take_dump, self.backup_path_db)
      self = <frappe.utils.backups.BackupGenerator object at 0x10547f710>
      older_than = 6
      ignore_files = True
      force = True
      last_db = False
      last_file = False
      last_private_file = False
      site_config_backup_path = False
  File "apps/frappe/frappe/utils/backups.py", line 520, in delete_if_step_fails
    raise e
      self = <frappe.utils.backups.BackupGenerator object at 0x10547f710>
      step = <bound method BackupGenerator.take_dump of <frappe.utils.backups.BackupGenerator object at 0x10547f710>>
      paths = ('./erpnexxt.local/private/backups/20250227_120016-erpnexxt_local-database.sql.gz',)
      path = './erpnexxt.local/private/backups/20250227_120016-erpnexxt_local-database.sql.gz'
  File "apps/frappe/frappe/utils/backups.py", line 515, in delete_if_step_fails
    step()
      self = <frappe.utils.backups.BackupGenerator object at 0x10547f710>
      step = <bound method BackupGenerator.take_dump of <frappe.utils.backups.BackupGenerator object at 0x10547f710>>
      paths = ('./erpnexxt.local/private/backups/20250227_120016-erpnexxt_local-database.sql.gz',)
      path = './erpnexxt.local/private/backups/20250227_120016-erpnexxt_local-database.sql.gz'
  File "apps/frappe/frappe/utils/backups.py", line 457, in take_dump
    frappe.throw(
      self = <frappe.utils.backups.BackupGenerator object at 0x10547f710>
      shlex = <module 'shlex' from '/opt/homebrew/Cellar/python@3.11/3.11.11/Frameworks/Python.framework/Versions/3.11/lib/python3.11/shlex.py'>
      frappe = <module 'frappe' from 'apps/frappe/frappe/__init__.py'>
      get_app_branch = <function get_app_branch at 0x1053e3d80>
      gzip_exc = '/usr/bin/gzip'
      database_header_content = ['begin frappe metadata', '[frappe]', 'version = 15.56.0', 'branch = master', 'end frappe metadata', '']
      generated_header = '-- begin frappe metadata\n-- [frappe]\n-- version = 15.56.0\n-- branch = master\n-- end frappe metadata\n-- \n'
      f = <_io.TextIOWrapper name='./erpnexxt.local/private/backups/20250227_120016-erpnexxt_local-database.sql.gz' encoding='UTF-8'>
      cmd = []
      extra = []
      get_command = <function get_command at 0x1053d2840>
      bin = None
      args = ['--user=_e7903427184a81b1', '--host=127.0.0.1', '--port=3306', '--password=eHVakHXsPB0Hhyx0', '--single-transaction', '--quick', '--lock-tables=false', '_e7903427184a81b1']
      bin_name = 'mariadb-dump'
  File "apps/frappe/frappe/__init__.py", line 603, in throw
    msgprint(
      msg = 'mariadb-dump not found in PATH! This is required to take a backup.'
      exc = <class 'frappe.exceptions.ExecutableNotFound'>
      title = None
      is_minimizable = False
      wide = False
      as_list = False
      primary_action = None
  File "apps/frappe/frappe/__init__.py", line 568, in msgprint
    _raise_exception()
      msg = 'mariadb-dump not found in PATH! This is required to take a backup.'
      title = None
      raise_exception = <class 'frappe.exceptions.ExecutableNotFound'>
      as_table = False
      as_list = False
      indicator = 'red'
      alert = False
      primary_action = None
      is_minimizable = False
      wide = False
      realtime = False
      sys = <module 'sys' (built-in)>
      _raise_exception = <function msgprint.<locals>._raise_exception at 0x1037cdda0>
      inspect = <module 'inspect' from '/opt/homebrew/Cellar/python@3.11/3.11.11/Frameworks/Python.framework/Versions/3.11/lib/python3.11/inspect.py'>
      out = {'message': 'mariadb-dump not found in PATH! This is required to take a backup.', 'title': 'Message', 'indicator': 'red', 'raise_exception': 1, '__frappe_exc_id': 'aa10fae81c3e77cb984aee21b2c55532833862cdf8d086bc38d3c0fc'}
  File "apps/frappe/frappe/__init__.py", line 519, in _raise_exception
    raise exc
      exc = ExecutableNotFound('mariadb-dump not found in PATH! This is required to take a backup.')
      inspect = <module 'inspect' from '/opt/homebrew/Cellar/python@3.11/3.11.11/Frameworks/Python.framework/Versions/3.11/lib/python3.11/inspect.py'>
      msg = 'mariadb-dump not found in PATH! This is required to take a backup.'
      out = {'message': 'mariadb-dump not found in PATH! This is required to take a backup.', 'title': 'Message', 'indicator': 'red', 'raise_exception': 1, '__frappe_exc_id': 'aa10fae81c3e77cb984aee21b2c55532833862cdf8d086bc38d3c0fc'}
      raise_exception = <class 'frappe.exceptions.ExecutableNotFound'>
frappe.exceptions.ExecutableNotFound: mariadb-dump not found in PATH! This is required to take a backup.
